Workbook

Sheet 클라우드힐스  분양분 견적서
BB1: *필독사항
BB2: 1. 호실 외 면적 및 금액, 용도 납부일자 비율등의 수치를 변경하지 말 것.
BB3: 2. 견적서의 내용 중 특이사항이나 문제가 될 내용이 있을 시엔 유케이아이디로 문의 부탁드립니다.
AT5: 작성일: | AV5: =TODAY() -> 45860
C6: 1. 분양호실 견적서 | AU6: [단위: 원]
C7: 호실 | E7: 용도 | K7: 면적 | W7: 공급가액 (VAT 별도) | AA7: 부가세 | AE7: 총 분양가 (VAT 포함) | AI7: 계약금 | AM7: 납입금 | AU7: 비고
K8: 전용면적 | O8: 공용면적 | S8: 분양면적 | AM8: 청약 납입금 | AQ8: 계약 납입금
K9: ㎡ | M9: 평 | O9: ㎡ | Q9: 평 | S9: ㎡ | U9: 평 | AI9: 0.1 | AM9: A | AQ9: B
C10: bt-414 | E10: =IF($C10="","",VLOOKUP($C10,'분양가테이블(부가세기입X)'!$A$6:$AF$358,2,FALSE)) -> 업무시설(지식산업센터) | I10: =IF($C10="","",VLOOKUP($C10,'분양가테이블(부가세기입X)'!$A$6:$AF$358,3,FALSE)) -> 분양 | K10: =IF($C10="","",VLOOKUP($C10,'분양가테이블(부가세기입X)'!$A$6:$AF$358,4,FALSE)) -> 105.76 | M10: =IF($C10="","",VLOOKUP($C10,'분양가테이블(부가세기입X)'!$A$6:$AF$358,5,FALSE)) -> 31.9924 | O10: =IF($C10="","",VLOOKUP($C10,'분양가테이블(부가세기입X)'!$A$6:$AF$358,12,FALSE)) -> 124.98 | Q10: =IF($C10="","",VLOOKUP($C10,'분양가테이블(부가세기입X)'!$A$6:$AF$358,13,FALSE)) -> 37.80645 | S10: =IF($C10="","",VLOOKUP($C10,'분양가테이블(부가세기입X)'!$A$6:$AF$358,6,FALSE)) -> 230.74 | U10: =IF($C10="","",VLOOKUP($C10,'분양가테이블(부가세기입X)'!$A$6:$AF$358,7,FALSE)) -> 69.79885 | W10: =IF($C10="","",VLOOKUP($C10,'분양가테이블(부가세기입X)'!$A$6:$AF$358,22,FALSE)) -> 1569000000 | Y10: =IF($C10="","",VLOOKUP($C10,'분양가테이블(부가세기입X)'!$A$6:$AF$358,3,FALSE)) -> 분양 | AA10: =IF($C10="","",VLOOKUP($C10,'분양가테이블(부가세기입X)'!$A$6:$AF$358,23,FALSE)) -> 86295000 | AC10: =IF($C10="","",VLOOKUP($C10,'분양가테이블(부가세기입X)'!$A$6:$AF$358,3,FALSE)) -> 분양 | AE10: =IF($C10="","",VLOOKUP($C10,'분양가테이블(부가세기입X)'!$A$6:$AF$358,24,FALSE)) -> 1655295000 | AG10: =IF($C10="","",VLOOKUP($C10,'분양가테이블(부가세기입X)'!$A$6:$AF$358,3,FALSE)) -> 분양 | AI10: =IF($C10="","",VLOOKUP($C10,'분양가테이블(부가세기입X)'!$A$6:$AF$358,25,FALSE)) -> 165529500 | AK10: =IF($C10="","",VLOOKUP($C10,'분양가테이블(부가세기입X)'!$A$6:$AF$358,3,FALSE)) -> 분양 | AQ10: =AI10 -> 165529500 | AS10: =IF($C10="","",VLOOKUP($C10,'분양가테이블(부가세기입X)'!$A$6:$AF$358,3,FALSE)) -> 분양
C11: bt-415 | E11: =IF($C11="","",VLOOKUP($C11,'분양가테이블(부가세기입X)'!$A$6:$AF$358,2,FALSE)) -> 업무시설(지식산업센터) | I11: =IF($C11="","",VLOOKUP($C11,'분양가테이블(부가세기입X)'!$A$6:$AF$358,3,FALSE)) -> 분양 | K11: =IF($C11="","",VLOOKUP($C11,'분양가테이블(부가세기입X)'!$A$6:$AF$358,4,FALSE)) -> 112.03 | M11: =IF($C11="","",VLOOKUP($C11,'분양가테이블(부가세기입X)'!$A$6:$AF$358,5,FALSE)) -> 33.889075 | O11: =IF($C11="","",VLOOKUP($C11,'분양가테이블(부가세기입X)'!$A$6:$AF$358,12,FALSE)) -> 132.38 | Q11: =IF($C11="","",VLOOKUP($C11,'분양가테이블(부가세기입X)'!$A$6:$AF$358,13,FALSE)) -> 40.04495 | S11: =IF($C11="","",VLOOKUP($C11,'분양가테이블(부가세기입X)'!$A$6:$AF$358,6,FALSE)) -> 244.41 | U11: =IF($C11="","",VLOOKUP($C11,'분양가테이블(부가세기입X)'!$A$6:$AF$358,7,FALSE)) -> 73.934025 | W11: =IF($C11="","",VLOOKUP($C11,'분양가테이블(부가세기입X)'!$A$6:$AF$358,22,FALSE)) -> 1662300000 | Y11: =IF($C11="","",VLOOKUP($C11,'분양가테이블(부가세기입X)'!$A$6:$AF$358,3,FALSE)) -> 분양 | AA11: =IF($C11="","",VLOOKUP($C11,'분양가테이블(부가세기입X)'!$A$6:$AF$358,23,FALSE)) -> 91426500 | AC11: =IF($C11="","",VLOOKUP($C11,'분양가테이블(부가세기입X)'!$A$6:$AF$358,3,FALSE)) -> 분양 | AE11: =IF($C11="","",VLOOKUP($C11,'분양가테이블(부가세기입X)'!$A$6:$AF$358,24,FALSE)) -> 1753726500 | AG11: =IF($C11="","",VLOOKUP($C11,'분양가테이블(부가세기입X)'!$A$6:$AF$358,3,FALSE)) -> 분양 | AI11: =IF($C11="","",VLOOKUP($C11,'분양가테이블(부가세기입X)'!$A$6:$AF$358,25,FALSE)) -> 175372650 | AK11: =IF($C11="","",VLOOKUP($C11,'분양가테이블(부가세기입X)'!$A$6:$AF$358,3,FALSE)) -> 분양 | AQ11: =AI11 -> 175372650 | AS11: =IF($C11="","",VLOOKUP($C11,'분양가테이블(부가세기입X)'!$A$6:$AF$358,3,FALSE)) -> 분양
C12: bt-416 | E12: =IF($C12="","",VLOOKUP($C12,'분양가테이블(부가세기입X)'!$A$6:$AF$358,2,FALSE)) -> 업무시설(지식산업센터) | I12: =IF($C12="","",VLOOKUP($C12,'분양가테이블(부가세기입X)'!$A$6:$AF$358,3,FALSE)) -> 분양 | K12: =IF($C12="","",VLOOKUP($C12,'분양가테이블(부가세기입X)'!$A$6:$AF$358,4,FALSE)) -> 78.75 | M12: =IF($C12="","",VLOOKUP($C12,'분양가테이블(부가세기입X)'!$A$6:$AF$358,5,FALSE)) -> 23.821875 | O12: =IF($C12="","",VLOOKUP($C12,'분양가테이블(부가세기입X)'!$A$6:$AF$358,12,FALSE)) -> 93.06 | Q12: =IF($C12="","",VLOOKUP($C12,'분양가테이블(부가세기입X)'!$A$6:$AF$358,13,FALSE)) -> 28.15065 | S12: =IF($C12="","",VLOOKUP($C12,'분양가테이블(부가세기입X)'!$A$6:$AF$358,6,FALSE)) -> 171.81 | U12: =IF($C12="","",VLOOKUP($C12,'분양가테이블(부가세기입X)'!$A$6:$AF$358,7,FALSE)) -> 51.972525 | W12: =IF($C12="","",VLOOKUP($C12,'분양가테이블(부가세기입X)'!$A$6:$AF$358,22,FALSE)) -> 1106100000 | Y12: =IF($C12="","",VLOOKUP($C12,'분양가테이블(부가세기입X)'!$A$6:$AF$358,3,FALSE)) -> 분양 | AA12: =IF($C12="","",VLOOKUP($C12,'분양가테이블(부가세기입X)'!$A$6:$AF$358,23,FALSE)) -> 60835500 | AC12: =IF($C12="","",VLOOKUP($C12,'분양가테이블(부가세기입X)'!$A$6:$AF$358,3,FALSE)) -> 분양 | AE12: =IF($C12="","",VLOOKUP($C12,'분양가테이블(부가세기입X)'!$A$6:$AF$358,24,FALSE)) -> 1166935500 | AG12: =IF($C12="","",VLOOKUP($C12,'분양가테이블(부가세기입X)'!$A$6:$AF$358,3,FALSE)) -> 분양 | AI12: =IF($C12="","",VLOOKUP($C12,'분양가테이블(부가세기입X)'!$A$6:$AF$358,25,FALSE)) -> 116693550 | AK12: =IF($C12="","",VLOOKUP($C12,'분양가테이블(부가세기입X)'!$A$6:$AF$358,3,FALSE)) -> 분양 | AQ12: =AI12 -> 116693550 | AS12: =IF($C12="","",VLOOKUP($C12,'분양가테이블(부가세기입X)'!$A$6:$AF$358,3,FALSE)) -> 분양
E13: =IF($C13="","",VLOOKUP($C13,'분양가테이블(부가세기입X)'!$A$6:$AF$358,2,FALSE)) | I13: =IF($C13="","",VLOOKUP($C13,'분양가테이블(부가세기입X)'!$A$6:$AF$358,3,FALSE)) | K13: =IF($C13="","",VLOOKUP($C13,'분양가테이블(부가세기입X)'!$A$6:$AF$358,4,FALSE)) | M13: =IF($C13="","",VLOOKUP($C13,'분양가테이블(부가세기입X)'!$A$6:$AF$358,5,FALSE)) | O13: =IF($C13="","",VLOOKUP($C13,'분양가테이블(부가세기입X)'!$A$6:$AF$358,12,FALSE)) | Q13: =IF($C13="","",VLOOKUP($C13,'분양가테이블(부가세기입X)'!$A$6:$AF$358,13,FALSE)) | S13: =IF($C13="","",VLOOKUP($C13,'분양가테이블(부가세기입X)'!$A$6:$AF$358,6,FALSE)) | U13: =IF($C13="","",VLOOKUP($C13,'분양가테이블(부가세기입X)'!$A$6:$AF$358,7,FALSE)) | W13: =IF($C13="","",VLOOKUP($C13,'분양가테이블(부가세기입X)'!$A$6:$AF$358,22,FALSE)) | Y13: =IF($C13="","",VLOOKUP($C13,'분양가테이블(부가세기입X)'!$A$6:$AF$358,3,FALSE)) | AA13: =IF($C13="","",VLOOKUP($C13,'분양가테이블(부가세기입X)'!$A$6:$AF$358,23,FALSE)) | AC13: =IF($C13="","",VLOOKUP($C13,'분양가테이블(부가세기입X)'!$A$6:$AF$358,3,FALSE)) | AE13: =IF($C13="","",VLOOKUP($C13,'분양가테이블(부가세기입X)'!$A$6:$AF$358,24,FALSE)) | AG13: =IF($C13="","",VLOOKUP($C13,'분양가테이블(부가세기입X)'!$A$6:$AF$358,3,FALSE)) | AI13: =IF($C13="","",VLOOKUP($C13,'분양가테이블(부가세기입X)'!$A$6:$AF$358,25,FALSE)) | AK13: =IF($C13="","",VLOOKUP($C13,'분양가테이블(부가세기입X)'!$A$6:$AF$358,3,FALSE)) | AQ13: =AI13 | AS13: =IF($C13="","",VLOOKUP($C13,'분양가테이블(부가세기입X)'!$A$6:$AF$358,3,FALSE))
E14: =IF($C14="","",VLOOKUP($C14,'분양가테이블(부가세기입X)'!$A$6:$AF$358,2,FALSE)) | I14: =IF($C14="","",VLOOKUP($C14,'분양가테이블(부가세기입X)'!$A$6:$AF$358,3,FALSE)) | K14: =IF($C14="","",VLOOKUP($C14,'분양가테이블(부가세기입X)'!$A$6:$AF$358,4,FALSE)) | M14: =IF($C14="","",VLOOKUP($C14,'분양가테이블(부가세기입X)'!$A$6:$AF$358,5,FALSE)) | O14: =IF($C14="","",VLOOKUP($C14,'분양가테이블(부가세기입X)'!$A$6:$AF$358,12,FALSE)) | Q14: =IF($C14="","",VLOOKUP($C14,'분양가테이블(부가세기입X)'!$A$6:$AF$358,13,FALSE)) | S14: =IF($C14="","",VLOOKUP($C14,'분양가테이블(부가세기입X)'!$A$6:$AF$358,6,FALSE)) | U14: =IF($C14="","",VLOOKUP($C14,'분양가테이블(부가세기입X)'!$A$6:$AF$358,7,FALSE)) | W14: =IF($C14="","",VLOOKUP($C14,'분양가테이블(부가세기입X)'!$A$6:$AF$358,22,FALSE)) | Y14: =IF($C14="","",VLOOKUP($C14,'분양가테이블(부가세기입X)'!$A$6:$AF$358,3,FALSE)) | AA14: =IF($C14="","",VLOOKUP($C14,'분양가테이블(부가세기입X)'!$A$6:$AF$358,23,FALSE)) | AC14: =IF($C14="","",VLOOKUP($C14,'분양가테이블(부가세기입X)'!$A$6:$AF$358,3,FALSE)) | AE14: =IF($C14="","",VLOOKUP($C14,'분양가테이블(부가세기입X)'!$A$6:$AF$358,24,FALSE)) | AG14: =IF($C14="","",VLOOKUP($C14,'분양가테이블(부가세기입X)'!$A$6:$AF$358,3,FALSE)) | AI14: =IF($C14="","",VLOOKUP($C14,'분양가테이블(부가세기입X)'!$A$6:$AF$358,25,FALSE)) | AK14: =IF($C14="","",VLOOKUP($C14,'분양가테이블(부가세기입X)'!$A$6:$AF$358,3,FALSE)) | AQ14: =AI14 | AS14: =IF($C14="","",VLOOKUP($C14,'분양가테이블(부가세기입X)'!$A$6:$AF$358,3,FALSE))
E15: =IF($C15="","",VLOOKUP($C15,'분양가테이블(부가세기입X)'!$A$6:$AF$358,2,FALSE)) | I15: =IF($C15="","",VLOOKUP($C15,'분양가테이블(부가세기입X)'!$A$6:$AF$358,3,FALSE)) | K15: =IF($C15="","",VLOOKUP($C15,'분양가테이블(부가세기입X)'!$A$6:$AF$358,4,FALSE)) | M15: =IF($C15="","",VLOOKUP($C15,'분양가테이블(부가세기입X)'!$A$6:$AF$358,5,FALSE)) | O15: =IF($C15="","",VLOOKUP($C15,'분양가테이블(부가세기입X)'!$A$6:$AF$358,12,FALSE)) | Q15: =IF($C15="","",VLOOKUP($C15,'분양가테이블(부가세기입X)'!$A$6:$AF$358,13,FALSE)) | S15: =IF($C15="","",VLOOKUP($C15,'분양가테이블(부가세기입X)'!$A$6:$AF$358,6,FALSE)) | U15: =IF($C15="","",VLOOKUP($C15,'분양가테이블(부가세기입X)'!$A$6:$AF$358,7,FALSE)) | W15: =IF($C15="","",VLOOKUP($C15,'분양가테이블(부가세기입X)'!$A$6:$AF$358,22,FALSE)) | Y15: =IF($C15="","",VLOOKUP($C15,'분양가테이블(부가세기입X)'!$A$6:$AF$358,3,FALSE)) | AA15: =IF($C15="","",VLOOKUP($C15,'분양가테이블(부가세기입X)'!$A$6:$AF$358,23,FALSE)) | AC15: =IF($C15="","",VLOOKUP($C15,'분양가테이블(부가세기입X)'!$A$6:$AF$358,3,FALSE)) | AE15: =IF($C15="","",VLOOKUP($C15,'분양가테이블(부가세기입X)'!$A$6:$AF$358,24,FALSE)) | AG15: =IF($C15="","",VLOOKUP($C15,'분양가테이블(부가세기입X)'!$A$6:$AF$358,3,FALSE)) | AI15: =IF($C15="","",VLOOKUP($C15,'분양가테이블(부가세기입X)'!$A$6:$AF$358,25,FALSE)) | AK15: =IF($C15="","",VLOOKUP($C15,'분양가테이블(부가세기입X)'!$A$6:$AF$358,3,FALSE)) | AQ15: =AI15 | AS15: =IF($C15="","",VLOOKUP($C15,'분양가테이블(부가세기입X)'!$A$6:$AF$358,3,FALSE))
E16: =IF($C16="","",VLOOKUP($C16,'분양가테이블(부가세기입X)'!$A$6:$AF$358,2,FALSE)) | I16: =IF($C16="","",VLOOKUP($C16,'분양가테이블(부가세기입X)'!$A$6:$AF$358,3,FALSE)) | K16: =IF($C16="","",VLOOKUP($C16,'분양가테이블(부가세기입X)'!$A$6:$AF$358,4,FALSE)) | M16: =IF($C16="","",VLOOKUP($C16,'분양가테이블(부가세기입X)'!$A$6:$AF$358,5,FALSE)) | O16: =IF($C16="","",VLOOKUP($C16,'분양가테이블(부가세기입X)'!$A$6:$AF$358,12,FALSE)) | Q16: =IF($C16="","",VLOOKUP($C16,'분양가테이블(부가세기입X)'!$A$6:$AF$358,13,FALSE)) | S16: =IF($C16="","",VLOOKUP($C16,'분양가테이블(부가세기입X)'!$A$6:$AF$358,6,FALSE)) | U16: =IF($C16="","",VLOOKUP($C16,'분양가테이블(부가세기입X)'!$A$6:$AF$358,7,FALSE)) | W16: =IF($C16="","",VLOOKUP($C16,'분양가테이블(부가세기입X)'!$A$6:$AF$358,22,FALSE)) | Y16: =IF($C16="","",VLOOKUP($C16,'분양가테이블(부가세기입X)'!$A$6:$AF$358,3,FALSE)) | AA16: =IF($C16="","",VLOOKUP($C16,'분양가테이블(부가세기입X)'!$A$6:$AF$358,23,FALSE)) | AC16: =IF($C16="","",VLOOKUP($C16,'분양가테이블(부가세기입X)'!$A$6:$AF$358,3,FALSE)) | AE16: =IF($C16="","",VLOOKUP($C16,'분양가테이블(부가세기입X)'!$A$6:$AF$358,24,FALSE)) | AG16: =IF($C16="","",VLOOKUP($C16,'분양가테이블(부가세기입X)'!$A$6:$AF$358,3,FALSE)) | AI16: =IF($C16="","",VLOOKUP($C16,'분양가테이블(부가세기입X)'!$A$6:$AF$358,25,FALSE)) | AK16: =IF($C16="","",VLOOKUP($C16,'분양가테이블(부가세기입X)'!$A$6:$AF$358,3,FALSE)) | AQ16: =AI16 | AS16: =IF($C16="","",VLOOKUP($C16,'분양가테이블(부가세기입X)'!$A$6:$AF$358,3,FALSE))
E17: =IF($C17="","",VLOOKUP($C17,'분양가테이블(부가세기입X)'!$A$6:$AF$358,2,FALSE)) | I17: =IF($C17="","",VLOOKUP($C17,'분양가테이블(부가세기입X)'!$A$6:$AF$358,3,FALSE)) | K17: =IF($C17="","",VLOOKUP($C17,'분양가테이블(부가세기입X)'!$A$6:$AF$358,4,FALSE)) | M17: =IF($C17="","",VLOOKUP($C17,'분양가테이블(부가세기입X)'!$A$6:$AF$358,5,FALSE)) | O17: =IF($C17="","",VLOOKUP($C17,'분양가테이블(부가세기입X)'!$A$6:$AF$358,12,FALSE)) | Q17: =IF($C17="","",VLOOKUP($C17,'분양가테이블(부가세기입X)'!$A$6:$AF$358,13,FALSE)) | S17: =IF($C17="","",VLOOKUP($C17,'분양가테이블(부가세기입X)'!$A$6:$AF$358,6,FALSE)) | U17: =IF($C17="","",VLOOKUP($C17,'분양가테이블(부가세기입X)'!$A$6:$AF$358,7,FALSE)) | W17: =IF($C17="","",VLOOKUP($C17,'분양가테이블(부가세기입X)'!$A$6:$AF$358,22,FALSE)) | Y17: =IF($C17="","",VLOOKUP($C17,'분양가테이블(부가세기입X)'!$A$6:$AF$358,3,FALSE)) | AA17: =IF($C17="","",VLOOKUP($C17,'분양가테이블(부가세기입X)'!$A$6:$AF$358,23,FALSE)) | AC17: =IF($C17="","",VLOOKUP($C17,'분양가테이블(부가세기입X)'!$A$6:$AF$358,3,FALSE)) | AE17: =IF($C17="","",VLOOKUP($C17,'분양가테이블(부가세기입X)'!$A$6:$AF$358,24,FALSE)) | AG17: =IF($C17="","",VLOOKUP($C17,'분양가테이블(부가세기입X)'!$A$6:$AF$358,3,FALSE)) | AI17: =IF($C17="","",VLOOKUP($C17,'분양가테이블(부가세기입X)'!$A$6:$AF$358,25,FALSE)) | AK17: =IF($C17="","",VLOOKUP($C17,'분양가테이블(부가세기입X)'!$A$6:$AF$358,3,FALSE)) | AQ17: =AI17 | AS17: =IF($C17="","",VLOOKUP($C17,'분양가테이블(부가세기입X)'!$A$6:$AF$358,3,FALSE))
E18: =IF($C18="","",VLOOKUP($C18,'분양가테이블(부가세기입X)'!$A$6:$AF$358,2,FALSE)) | I18: =IF($C18="","",VLOOKUP($C18,'분양가테이블(부가세기입X)'!$A$6:$AF$358,3,FALSE)) | K18: =IF($C18="","",VLOOKUP($C18,'분양가테이블(부가세기입X)'!$A$6:$AF$358,4,FALSE)) | M18: =IF($C18="","",VLOOKUP($C18,'분양가테이블(부가세기입X)'!$A$6:$AF$358,5,FALSE)) | O18: =IF($C18="","",VLOOKUP($C18,'분양가테이블(부가세기입X)'!$A$6:$AF$358,12,FALSE)) | Q18: =IF($C18="","",VLOOKUP($C18,'분양가테이블(부가세기입X)'!$A$6:$AF$358,13,FALSE)) | S18: =IF($C18="","",VLOOKUP($C18,'분양가테이블(부가세기입X)'!$A$6:$AF$358,6,FALSE)) | U18: =IF($C18="","",VLOOKUP($C18,'분양가테이블(부가세기입X)'!$A$6:$AF$358,7,FALSE)) | W18: =IF($C18="","",VLOOKUP($C18,'분양가테이블(부가세기입X)'!$A$6:$AF$358,22,FALSE)) | Y18: =IF($C18="","",VLOOKUP($C18,'분양가테이블(부가세기입X)'!$A$6:$AF$358,3,FALSE)) | AA18: =IF($C18="","",VLOOKUP($C18,'분양가테이블(부가세기입X)'!$A$6:$AF$358,23,FALSE)) | AC18: =IF($C18="","",VLOOKUP($C18,'분양가테이블(부가세기입X)'!$A$6:$AF$358,3,FALSE)) | AE18: =IF($C18="","",VLOOKUP($C18,'분양가테이블(부가세기입X)'!$A$6:$AF$358,24,FALSE)) | AG18: =IF($C18="","",VLOOKUP($C18,'분양가테이블(부가세기입X)'!$A$6:$AF$358,3,FALSE)) | AI18: =IF($C18="","",VLOOKUP($C18,'분양가테이블(부가세기입X)'!$A$6:$AF$358,25,FALSE)) | AK18: =IF($C18="","",VLOOKUP($C18,'분양가테이블(부가세기입X)'!$A$6:$AF$358,3,FALSE)) | AQ18: =AI18 | AS18: =IF($C18="","",VLOOKUP($C18,'분양가테이블(부가세기입X)'!$A$6:$AF$358,3,FALSE))
E19: =IF($C19="","",VLOOKUP($C19,'분양가테이블(부가세기입X)'!$A$6:$AF$358,2,FALSE)) | I19: =IF($C19="","",VLOOKUP($C19,'분양가테이블(부가세기입X)'!$A$6:$AF$358,3,FALSE)) | K19: =IF($C19="","",VLOOKUP($C19,'분양가테이블(부가세기입X)'!$A$6:$AF$358,4,FALSE)) | M19: =IF($C19="","",VLOOKUP($C19,'분양가테이블(부가세기입X)'!$A$6:$AF$358,5,FALSE)) | O19: =IF($C19="","",VLOOKUP($C19,'분양가테이블(부가세기입X)'!$A$6:$AF$358,12,FALSE)) | Q19: =IF($C19="","",VLOOKUP($C19,'분양가테이블(부가세기입X)'!$A$6:$AF$358,13,FALSE)) | S19: =IF($C19="","",VLOOKUP($C19,'분양가테이블(부가세기입X)'!$A$6:$AF$358,6,FALSE)) | U19: =IF($C19="","",VLOOKUP($C19,'분양가테이블(부가세기입X)'!$A$6:$AF$358,7,FALSE)) | W19: =IF($C19="","",VLOOKUP($C19,'분양가테이블(부가세기입X)'!$A$6:$AF$358,22,FALSE)) | Y19: =IF($C19="","",VLOOKUP($C19,'분양가테이블(부가세기입X)'!$A$6:$AF$358,3,FALSE)) | AA19: =IF($C19="","",VLOOKUP($C19,'분양가테이블(부가세기입X)'!$A$6:$AF$358,23,FALSE)) | AC19: =IF($C19="","",VLOOKUP($C19,'분양가테이블(부가세기입X)'!$A$6:$AF$358,3,FALSE)) | AE19: =IF($C19="","",VLOOKUP($C19,'분양가테이블(부가세기입X)'!$A$6:$AF$358,24,FALSE)) | AG19: =IF($C19="","",VLOOKUP($C19,'분양가테이블(부가세기입X)'!$A$6:$AF$358,3,FALSE)) | AI19: =IF($C19="","",VLOOKUP($C19,'분양가테이블(부가세기입X)'!$A$6:$AF$358,25,FALSE)) | AK19: =IF($C19="","",VLOOKUP($C19,'분양가테이블(부가세기입X)'!$A$6:$AF$358,3,FALSE)) | AQ19: =AI19 | AS19: =IF($C19="","",VLOOKUP($C19,'분양가테이블(부가세기입X)'!$A$6:$AF$358,3,FALSE))
E20: =IF($C20="","",VLOOKUP($C20,'분양가테이블(부가세기입X)'!$A$6:$AF$358,2,FALSE)) | I20: =IF($C20="","",VLOOKUP($C20,'분양가테이블(부가세기입X)'!$A$6:$AF$358,3,FALSE)) | K20: =IF($C20="","",VLOOKUP($C20,'분양가테이블(부가세기입X)'!$A$6:$AF$358,4,FALSE)) | M20: =IF($C20="","",VLOOKUP($C20,'분양가테이블(부가세기입X)'!$A$6:$AF$358,5,FALSE)) | O20: =IF($C20="","",VLOOKUP($C20,'분양가테이블(부가세기입X)'!$A$6:$AF$358,12,FALSE)) | Q20: =IF($C20="","",VLOOKUP($C20,'분양가테이블(부가세기입X)'!$A$6:$AF$358,13,FALSE)) | S20: =IF($C20="","",VLOOKUP($C20,'분양가테이블(부가세기입X)'!$A$6:$AF$358,6,FALSE)) | U20: =IF($C20="","",VLOOKUP($C20,'분양가테이블(부가세기입X)'!$A$6:$AF$358,7,FALSE)) | W20: =IF($C20="","",VLOOKUP($C20,'분양가테이블(부가세기입X)'!$A$6:$AF$358,22,FALSE)) | Y20: =IF($C20="","",VLOOKUP($C20,'분양가테이블(부가세기입X)'!$A$6:$AF$358,3,FALSE)) | AA20: =IF($C20="","",VLOOKUP($C20,'분양가테이블(부가세기입X)'!$A$6:$AF$358,23,FALSE)) | AC20: =IF($C20="","",VLOOKUP($C20,'분양가테이블(부가세기입X)'!$A$6:$AF$358,3,FALSE)) | AE20: =IF($C20="","",VLOOKUP($C20,'분양가테이블(부가세기입X)'!$A$6:$AF$358,24,FALSE)) | AG20: =IF($C20="","",VLOOKUP($C20,'분양가테이블(부가세기입X)'!$A$6:$AF$358,3,FALSE)) | AI20: =IF($C20="","",VLOOKUP($C20,'분양가테이블(부가세기입X)'!$A$6:$AF$358,25,FALSE)) | AK20: =IF($C20="","",VLOOKUP($C20,'분양가테이블(부가세기입X)'!$A$6:$AF$358,3,FALSE)) | AQ20: =AI20 | AS20: =IF($C20="","",VLOOKUP($C20,'분양가테이블(부가세기입X)'!$A$6:$AF$358,3,FALSE))
E21: =IF($C21="","",VLOOKUP($C21,'분양가테이블(부가세기입X)'!$A$6:$AF$358,2,FALSE)) | I21: =IF($C21="","",VLOOKUP($C21,'분양가테이블(부가세기입X)'!$A$6:$AF$358,3,FALSE)) | K21: =IF($C21="","",VLOOKUP($C21,'분양가테이블(부가세기입X)'!$A$6:$AF$358,4,FALSE)) | M21: =IF($C21="","",VLOOKUP($C21,'분양가테이블(부가세기입X)'!$A$6:$AF$358,5,FALSE)) | O21: =IF($C21="","",VLOOKUP($C21,'분양가테이블(부가세기입X)'!$A$6:$AF$358,12,FALSE)) | Q21: =IF($C21="","",VLOOKUP($C21,'분양가테이블(부가세기입X)'!$A$6:$AF$358,13,FALSE)) | S21: =IF($C21="","",VLOOKUP($C21,'분양가테이블(부가세기입X)'!$A$6:$AF$358,6,FALSE)) | U21: =IF($C21="","",VLOOKUP($C21,'분양가테이블(부가세기입X)'!$A$6:$AF$358,7,FALSE)) | W21: =IF($C21="","",VLOOKUP($C21,'분양가테이블(부가세기입X)'!$A$6:$AF$358,22,FALSE)) | Y21: =IF($C21="","",VLOOKUP($C21,'분양가테이블(부가세기입X)'!$A$6:$AF$358,3,FALSE)) | AA21: =IF($C21="","",VLOOKUP($C21,'분양가테이블(부가세기입X)'!$A$6:$AF$358,23,FALSE)) | AC21: =IF($C21="","",VLOOKUP($C21,'분양가테이블(부가세기입X)'!$A$6:$AF$358,3,FALSE)) | AE21: =IF($C21="","",VLOOKUP($C21,'분양가테이블(부가세기입X)'!$A$6:$AF$358,24,FALSE)) | AG21: =IF($C21="","",VLOOKUP($C21,'분양가테이블(부가세기입X)'!$A$6:$AF$358,3,FALSE)) | AI21: =IF($C21="","",VLOOKUP($C21,'분양가테이블(부가세기입X)'!$A$6:$AF$358,25,FALSE)) | AK21: =IF($C21="","",VLOOKUP($C21,'분양가테이블(부가세기입X)'!$A$6:$AF$358,3,FALSE)) | AQ21: =AI21 | AS21: =IF($C21="","",VLOOKUP($C21,'분양가테이블(부가세기입X)'!$A$6:$AF$358,3,FALSE))
E22: =IF($C22="","",VLOOKUP($C22,'분양가테이블(부가세기입X)'!$A$6:$AF$358,2,FALSE)) | I22: =IF($C22="","",VLOOKUP($C22,'분양가테이블(부가세기입X)'!$A$6:$AF$358,3,FALSE)) | K22: =IF($C22="","",VLOOKUP($C22,'분양가테이블(부가세기입X)'!$A$6:$AF$358,4,FALSE)) | M22: =IF($C22="","",VLOOKUP($C22,'분양가테이블(부가세기입X)'!$A$6:$AF$358,5,FALSE)) | O22: =IF($C22="","",VLOOKUP($C22,'분양가테이블(부가세기입X)'!$A$6:$AF$358,12,FALSE)) | Q22: =IF($C22="","",VLOOKUP($C22,'분양가테이블(부가세기입X)'!$A$6:$AF$358,13,FALSE)) | S22: =IF($C22="","",VLOOKUP($C22,'분양가테이블(부가세기입X)'!$A$6:$AF$358,6,FALSE)) | U22: =IF($C22="","",VLOOKUP($C22,'분양가테이블(부가세기입X)'!$A$6:$AF$358,7,FALSE)) | W22: =IF($C22="","",VLOOKUP($C22,'분양가테이블(부가세기입X)'!$A$6:$AF$358,22,FALSE)) | Y22: =IF($C22="","",VLOOKUP($C22,'분양가테이블(부가세기입X)'!$A$6:$AF$358,3,FALSE)) | AA22: =IF($C22="","",VLOOKUP($C22,'분양가테이블(부가세기입X)'!$A$6:$AF$358,23,FALSE)) | AC22: =IF($C22="","",VLOOKUP($C22,'분양가테이블(부가세기입X)'!$A$6:$AF$358,3,FALSE)) | AE22: =IF($C22="","",VLOOKUP($C22,'분양가테이블(부가세기입X)'!$A$6:$AF$358,24,FALSE)) | AG22: =IF($C22="","",VLOOKUP($C22,'분양가테이블(부가세기입X)'!$A$6:$AF$358,3,FALSE)) | AI22: =IF($C22="","",VLOOKUP($C22,'분양가테이블(부가세기입X)'!$A$6:$AF$358,25,FALSE)) | AK22: =IF($C22="","",VLOOKUP($C22,'분양가테이블(부가세기입X)'!$A$6:$AF$358,3,FALSE)) | AQ22: =AI22 | AS22: =IF($C22="","",VLOOKUP($C22,'분양가테이블(부가세기입X)'!$A$6:$AF$358,3,FALSE))
E23: =IF($C23="","",VLOOKUP($C23,'분양가테이블(부가세기입X)'!$A$6:$AF$358,2,FALSE)) | I23: =IF($C23="","",VLOOKUP($C23,'분양가테이블(부가세기입X)'!$A$6:$AF$358,3,FALSE)) | K23: =IF($C23="","",VLOOKUP($C23,'분양가테이블(부가세기입X)'!$A$6:$AF$358,4,FALSE)) | M23: =IF($C23="","",VLOOKUP($C23,'분양가테이블(부가세기입X)'!$A$6:$AF$358,5,FALSE)) | O23: =IF($C23="","",VLOOKUP($C23,'분양가테이블(부가세기입X)'!$A$6:$AF$358,12,FALSE)) | Q23: =IF($C23="","",VLOOKUP($C23,'분양가테이블(부가세기입X)'!$A$6:$AF$358,13,FALSE)) | S23: =IF($C23="","",VLOOKUP($C23,'분양가테이블(부가세기입X)'!$A$6:$AF$358,6,FALSE)) | U23: =IF($C23="","",VLOOKUP($C23,'분양가테이블(부가세기입X)'!$A$6:$AF$358,7,FALSE)) | W23: =IF($C23="","",VLOOKUP($C23,'분양가테이블(부가세기입X)'!$A$6:$AF$358,22,FALSE)) | Y23: =IF($C23="","",VLOOKUP($C23,'분양가테이블(부가세기입X)'!$A$6:$AF$358,3,FALSE)) | AA23: =IF($C23="","",VLOOKUP($C23,'분양가테이블(부가세기입X)'!$A$6:$AF$358,23,FALSE)) | AC23: =IF($C23="","",VLOOKUP($C23,'분양가테이블(부가세기입X)'!$A$6:$AF$358,3,FALSE)) | AE23: =IF($C23="","",VLOOKUP($C23,'분양가테이블(부가세기입X)'!$A$6:$AF$358,24,FALSE)) | AG23: =IF($C23="","",VLOOKUP($C23,'분양가테이블(부가세기입X)'!$A$6:$AF$358,3,FALSE)) | AI23: =IF($C23="","",VLOOKUP($C23,'분양가테이블(부가세기입X)'!$A$6:$AF$358,25,FALSE)) | AK23: =IF($C23="","",VLOOKUP($C23,'분양가테이블(부가세기입X)'!$A$6:$AF$358,3,FALSE)) | AQ23: =AI23 | AS23: =IF($C23="","",VLOOKUP($C23,'분양가테이블(부가세기입X)'!$A$6:$AF$358,3,FALSE))
E24: =IF($C24="","",VLOOKUP($C24,'분양가테이블(부가세기입X)'!$A$6:$AF$358,2,FALSE)) | I24: =IF($C24="","",VLOOKUP($C24,'분양가테이블(부가세기입X)'!$A$6:$AF$358,3,FALSE)) | K24: =IF($C24="","",VLOOKUP($C24,'분양가테이블(부가세기입X)'!$A$6:$AF$358,4,FALSE)) | M24: =IF($C24="","",VLOOKUP($C24,'분양가테이블(부가세기입X)'!$A$6:$AF$358,5,FALSE)) | O24: =IF($C24="","",VLOOKUP($C24,'분양가테이블(부가세기입X)'!$A$6:$AF$358,12,FALSE)) | Q24: =IF($C24="","",VLOOKUP($C24,'분양가테이블(부가세기입X)'!$A$6:$AF$358,13,FALSE)) | S24: =IF($C24="","",VLOOKUP($C24,'분양가테이블(부가세기입X)'!$A$6:$AF$358,6,FALSE)) | U24: =IF($C24="","",VLOOKUP($C24,'분양가테이블(부가세기입X)'!$A$6:$AF$358,7,FALSE)) | W24: =IF($C24="","",VLOOKUP($C24,'분양가테이블(부가세기입X)'!$A$6:$AF$358,22,FALSE)) | Y24: =IF($C24="","",VLOOKUP($C24,'분양가테이블(부가세기입X)'!$A$6:$AF$358,3,FALSE)) | AA24: =IF($C24="","",VLOOKUP($C24,'분양가테이블(부가세기입X)'!$A$6:$AF$358,23,FALSE)) | AC24: =IF($C24="","",VLOOKUP($C24,'분양가테이블(부가세기입X)'!$A$6:$AF$358,3,FALSE)) | AE24: =IF($C24="","",VLOOKUP($C24,'분양가테이블(부가세기입X)'!$A$6:$AF$358,24,FALSE)) | AG24: =IF($C24="","",VLOOKUP($C24,'분양가테이블(부가세기입X)'!$A$6:$AF$358,3,FALSE)) | AI24: =IF($C24="","",VLOOKUP($C24,'분양가테이블(부가세기입X)'!$A$6:$AF$358,25,FALSE)) | AK24: =IF($C24="","",VLOOKUP($C24,'분양가테이블(부가세기입X)'!$A$6:$AF$358,3,FALSE)) | AQ24: =AI24 | AS24: =IF($C24="","",VLOOKUP($C24,'분양가테이블(부가세기입X)'!$A$6:$AF$358,3,FALSE))
... E37: =IF($C37="","",VLOOKUP($C37,'분양가테이블(부가세기입X)'!$A$6:$AF$358,2,FALSE)) | I37: =IF($C37="","",VLOOKUP($C37,'분양가테이블(부가세기입X)'!$A$6:$AF$358,3,FALSE)) | K37: =IF($C37="","",VLOOKUP($C37,'분양가테이블(부가세기입X)'!$A$6:$AF$358,4,FALSE)) | M37: =IF($C37="","",VLOOKUP($C37,'분양가테이블(부가세기입X)'!$A$6:$AF$358,5,FALSE)) | O37: =IF($C37="","",VLOOKUP($C37,'분양가테이블(부가세기입X)'!$A$6:$AF$358,12,FALSE)) | Q37: =IF($C37="","",VLOOKUP($C37,'분양가테이블(부가세기입X)'!$A$6:$AF$358,13,FALSE)) | S37: =IF($C37="","",VLOOKUP($C37,'분양가테이블(부가세기입X)'!$A$6:$AF$358,6,FALSE)) | U37: =IF($C37="","",VLOOKUP($C37,'분양가테이블(부가세기입X)'!$A$6:$AF$358,7,FALSE)) | W37: =IF($C37="","",VLOOKUP($C37,'분양가테이블(부가세기입X)'!$A$6:$AF$358,22,FALSE)) | Y37: =IF($C37="","",VLOOKUP($C37,'분양가테이블(부가세기입X)'!$A$6:$AF$358,3,FALSE)) | AA37: =IF($C37="","",VLOOKUP($C37,'분양가테이블(부가세기입X)'!$A$6:$AF$358,23,FALSE)) | AC37: =IF($C37="","",VLOOKUP($C37,'분양가테이블(부가세기입X)'!$A$6:$AF$358,3,FALSE)) | AE37: =IF($C37="","",VLOOKUP($C37,'분양가테이블(부가세기입X)'!$A$6:$AF$358,24,FALSE)) | AG37: =IF($C37="","",VLOOKUP($C37,'분양가테이블(부가세기입X)'!$A$6:$AF$358,3,FALSE)) | AI37: =IF($C37="","",VLOOKUP($C37,'분양가테이블(부가세기입X)'!$A$6:$AF$358,25,FALSE)) | AK37: =IF($C37="","",VLOOKUP($C37,'분양가테이블(부가세기입X)'!$A$6:$AF$358,3,FALSE)) | AQ37: =AI37 | AS37: =IF($C37="","",VLOOKUP($C37,'분양가테이블(부가세기입X)'!$A$6:$AF$358,3,FALSE))
C38: 합 계 | K38: =SUM(K10:L37) -> 296.54 | M38: =SUM(M10:N37) -> 89.70335 | O38: =SUM(O10:P37) -> 350.42 | Q38: =SUM(Q10:R37) -> 106.00205 | S38: =SUM(S10:T37) -> 646.96 | U38: =SUM(U10:V37) -> 195.7054 | W38: =SUM(W10:Z37) -> 4337400000 | AA38: =SUM(AA10:AD37) -> 2.38557e+08 | AE38: =SUM(AE10:AH37) -> 4575957000 | AI38: =SUM(AI10:AL37) -> 457595700 | AM38: =SUM(AM10:AP37) -> 0 | AQ38: =SUM(AQ10:AT37) -> 457595700 | AU38: -
C40: 2. 납부조건 (분양호실에 해당) | V40: [단위: 원] | AB40: 3. 납부조건 (임대호실에 해당) | AU40: [단위: 원]
C41: 구분 | G41: 비율 | I41: 납부일자 | M41: 공급가액 | Q41: 부가세 | U41: 총 분양가 | AB41: 구분 | AF41: 비율 | AH41: 납부일자 | AL41: 보증금 | AQ41: 임대가 | AU41: 비고
C42: 계약금 | G42: 0.1 | I42: 계약일 | M42: =W38*10% -> 433740000 | Q42: =AA38*10% -> 23855700 | U42: =M42+Q42 -> 457595700 | AB42: 계약보증금 | AF42: 1 | AH42: -
C43: 중도금 | G43: - | I43: - | M43: - | Q43: - | U43: - | AB43: 계약금 | AF43: 0.1 | AH43: 계약일
C44: 잔금 | G44: 0.9 | I44: 입주지정일 | M44: =W38*90% -> 3903660000 | Q44: =AA38*90% -> 2.147013e+08 | U44: =M44+Q44 -> 4118361300 | AB44: 중도금 | AF44: - | AH44: 해당없음
C45: 합계 | G45: 1 | I45: - | M45: =W38 -> 4337400000 | Q45: =AA38 -> 2.38557e+08 | U45: =M45+Q45 -> 4575957000 | AB45: 잔금 | AF45: 0.9 | AH45: 입주지정일
C47: 4. 계약금 입금계좌 | W47: 5. 계약시 구비서류
C48: 은행명 | G48: 계좌번호 | P48: 예금주 | W48: 개인 | AB48: 정부수입인지 (사본제출, 원본 계약자 보관 필수) 인감증명서 1부, 주민등록등본 1부, 신분증 사본(복사), 개인인감도장
C49: IBK기업은행 | G49: 694-022383-01-022 | P49: 신한자산신탁 주식회사
W50: 개인 사업자 | AB50: 정부수입인지 (사본제출, 원본 계약자 보관 필수) 인감증명서 1부, 주민등록등본 1부, 대표자 신분증 사본(복사), 사업자등록증 1부, 개인 인감도장
C51: 입금 표기 예시 (필독)
C52: 호실+계약자명or상호명 = (예시) 101호 홍길동 / 101호 홍길동산업 | W52: 법인 사업자 | AB52: 정부수입인지 (사본제출, 원본 계약자 보관 필수) 법인인감증명서 1부, 법인등기부등본 1부, 대표자 신분증 사본(복사), 사업자등록증 1부, 법인 인감도장
C54: ※ 계약금 입금 전 계좌번호 확인 후 담당자에게 연락하여 입금하시길 바랍니다. | W54: ※ 대리인 계약시: 상기 구비서류 외 위임장 1부, 계약자 인감증명서(위임용) 2부, 대리인 신분증 필수

Sheet 클라우드힐스 임대분 견적서
BB1: *필독사항
BB2: 1. 호실 외 면적 및 금액, 용도 납부일자 비율등의 수치를 변경하지 말 것.
BB3: 2. 견적서의 내용 중 특이사항이나 문제가 될 내용이 있을 시엔 유케이아이디로 문의 부탁드립니다.
AT5: 작성일: | AV5: =TODAY() -> 45860
C6: 1. 임대호실 견적서 | AU6: [단위: 원]
C7: 호실 | E7: 용도 | K7: 면적 | W7: 월임대료 (VAT 별도) | AA7: 부가세 | AE7: 총 월임대료 (VAT 포함) | AI7: 보증금(계약금) | AM7: 납입금 | AU7: 총 보증금
K8: 전용면적 | O8: 공용면적 | S8: 분양면적 | AM8: 청약 납입금 | AQ8: 계약 납입금
K9: ㎡ | M9: 평 | O9: ㎡ | Q9: 평 | S9: ㎡ | U9: 평 | AI9: 0.1 | AM9: A | AQ9: B
E10: =IF($C10="","",VLOOKUP($C10,'분양가테이블(부가세기입X)'!$A$6:$AF$400,2,FALSE)) | I10: =IF($C10="","",VLOOKUP($C10,'분양가테이블(부가세기입X)'!$A$6:$AF$400,3,FALSE)) | K10: =IF($C10="","",VLOOKUP($C10,'분양가테이블(부가세기입X)'!$A$6:$AF$400,4,FALSE)) | M10: =IF($C10="","",VLOOKUP($C10,'분양가테이블(부가세기입X)'!$A$6:$AF$400,5,FALSE)) | O10: =IF($C10="","",VLOOKUP($C10,'분양가테이블(부가세기입X)'!$A$6:$AF$400,12,FALSE)) | Q10: =IF($C10="","",VLOOKUP($C10,'분양가테이블(부가세기입X)'!$A$6:$AF$400,13,FALSE)) | S10: =IF($C10="","",VLOOKUP($C10,'분양가테이블(부가세기입X)'!$A$6:$AF$400,6,FALSE)) | U10: =IF($C10="","",VLOOKUP($C10,'분양가테이블(부가세기입X)'!$A$6:$AF$400,7,FALSE)) | W10: =IF($C10="","",VLOOKUP($C10,'분양가테이블(부가세기입X)'!$A$6:$AF$400,17,FALSE)) | AA10: =IF($C10="","",VLOOKUP($C10,'분양가테이블(부가세기입X)'!$A$6:$AF$400,23,FALSE)) | AE10: =IF($C10="","",VLOOKUP($C10,'분양가테이블(부가세기입X)'!$A$6:$AF$400,24,FALSE)) | AI10: =IF($C10="","",VLOOKUP($C10,'분양가테이블(부가세기입X)'!$A$6:$AF$400,26,FALSE)) | AQ10: =AI10 | AU10: =IF($C10="","",VLOOKUP($C10,'분양가테이블(부가세기입X)'!$A$6:$AF$400,18,FALSE))
C11: bt-1104 | E11: =IF($C11="","",VLOOKUP($C11,'분양가테이블(부가세기입X)'!$A$6:$AF$400,2,FALSE)) -> 업무시설(지식산업센터) | I11: =IF($C11="","",VLOOKUP($C11,'분양가테이블(부가세기입X)'!$A$6:$AF$400,3,FALSE)) -> 임대 | K11: =IF($C11="","",VLOOKUP($C11,'분양가테이블(부가세기입X)'!$A$6:$AF$400,4,FALSE)) -> 81.69 | M11: =IF($C11="","",VLOOKUP($C11,'분양가테이블(부가세기입X)'!$A$6:$AF$400,5,FALSE)) -> 24.711225 | O11: =IF($C11="","",VLOOKUP($C11,'분양가테이블(부가세기입X)'!$A$6:$AF$400,12,FALSE)) -> 96.53 | Q11: =IF($C11="","",VLOOKUP($C11,'분양가테이블(부가세기입X)'!$A$6:$AF$400,13,FALSE)) -> 29.200325 | S11: =IF($C11="","",VLOOKUP($C11,'분양가테이블(부가세기입X)'!$A$6:$AF$400,6,FALSE)) -> 178.22 | U11: =IF($C11="","",VLOOKUP($C11,'분양가테이블(부가세기입X)'!$A$6:$AF$400,7,FALSE)) -> 53.91155 | W11: =IF($C11="","",VLOOKUP($C11,'분양가테이블(부가세기입X)'!$A$6:$AF$400,17,FALSE)) -> 2857000 | AA11: =IF($C11="","",VLOOKUP($C11,'분양가테이블(부가세기입X)'!$A$6:$AF$400,23,FALSE)) -> 285700 | AE11: =IF($C11="","",VLOOKUP($C11,'분양가테이블(부가세기입X)'!$A$6:$AF$400,24,FALSE)) -> 3142700 | AI11: =IF($C11="","",VLOOKUP($C11,'분양가테이블(부가세기입X)'!$A$6:$AF$400,26,FALSE)) -> 2857000 | AQ11: =AI11 -> 2857000 | AU11: =IF($C11="","",VLOOKUP($C11,'분양가테이블(부가세기입X)'!$A$6:$AF$400,18,FALSE)) -> 28570000
C12: bt-1105 | E12: =IF($C12="","",VLOOKUP($C12,'분양가테이블(부가세기입X)'!$A$6:$AF$400,2,FALSE)) -> 업무시설(지식산업센터) | I12: =IF($C12="","",VLOOKUP($C12,'분양가테이블(부가세기입X)'!$A$6:$AF$400,3,FALSE)) -> 임대 | K12: =IF($C12="","",VLOOKUP($C12,'분양가테이블(부가세기입X)'!$A$6:$AF$400,4,FALSE)) -> 81.69 | M12: =IF($C12="","",VLOOKUP($C12,'분양가테이블(부가세기입X)'!$A$6:$AF$400,5,FALSE)) -> 24.711225 | O12: =IF($C12="","",VLOOKUP($C12,'분양가테이블(부가세기입X)'!$A$6:$AF$400,12,FALSE)) -> 96.53 | Q12: =IF($C12="","",VLOOKUP($C12,'분양가테이블(부가세기입X)'!$A$6:$AF$400,13,FALSE)) -> 29.200325 | S12: =IF($C12="","",VLOOKUP($C12,'분양가테이블(부가세기입X)'!$A$6:$AF$400,6,FALSE)) -> 178.22 | U12: =IF($C12="","",VLOOKUP($C12,'분양가테이블(부가세기입X)'!$A$6:$AF$400,7,FALSE)) -> 53.91155 | W12: =IF($C12="","",VLOOKUP($C12,'분양가테이블(부가세기입X)'!$A$6:$AF$400,17,FALSE)) -> 2857000 | AA12: =IF($C12="","",VLOOKUP($C12,'분양가테이블(부가세기입X)'!$A$6:$AF$400,23,FALSE)) -> 285700 | AE12: =IF($C12="","",VLOOKUP($C12,'분양가테이블(부가세기입X)'!$A$6:$AF$400,24,FALSE)) -> 3142700 | AI12: =IF($C12="","",VLOOKUP($C12,'분양가테이블(부가세기입X)'!$A$6:$AF$400,26,FALSE)) -> 2857000 | AQ12: =AI12 -> 2857000 | AU12: =IF($C12="","",VLOOKUP($C12,'분양가테이블(부가세기입X)'!$A$6:$AF$400,18,FALSE)) -> 28570000
C13: bt-1107 | E13: =IF($C13="","",VLOOKUP($C13,'분양가테이블(부가세기입X)'!$A$6:$AF$400,2,FALSE)) -> 업무시설(지식산업센터) | I13: =IF($C13="","",VLOOKUP($C13,'분양가테이블(부가세기입X)'!$A$6:$AF$400,3,FALSE)) -> 임대 | K13: =IF($C13="","",VLOOKUP($C13,'분양가테이블(부가세기입X)'!$A$6:$AF$400,4,FALSE)) -> 81.69 | M13: =IF($C13="","",VLOOKUP($C13,'분양가테이블(부가세기입X)'!$A$6:$AF$400,5,FALSE)) -> 24.711225 | O13: =IF($C13="","",VLOOKUP($C13,'분양가테이블(부가세기입X)'!$A$6:$AF$400,12,FALSE)) -> 96.53 | Q13: =IF($C13="","",VLOOKUP($C13,'분양가테이블(부가세기입X)'!$A$6:$AF$400,13,FALSE)) -> 29.200325 | S13: =IF($C13="","",VLOOKUP($C13,'분양가테이블(부가세기입X)'!$A$6:$AF$400,6,FALSE)) -> 178.22 | U13: =IF($C13="","",VLOOKUP($C13,'분양가테이블(부가세기입X)'!$A$6:$AF$400,7,FALSE)) -> 53.91155 | W13: =IF($C13="","",VLOOKUP($C13,'분양가테이블(부가세기입X)'!$A$6:$AF$400,17,FALSE)) -> 2857000 | AA13: =IF($C13="","",VLOOKUP($C13,'분양가테이블(부가세기입X)'!$A$6:$AF$400,23,FALSE)) -> 285700 | AE13: =IF($C13="","",VLOOKUP($C13,'분양가테이블(부가세기입X)'!$A$6:$AF$400,24,FALSE)) -> 3142700 | AI13: =IF($C13="","",VLOOKUP($C13,'분양가테이블(부가세기입X)'!$A$6:$AF$400,26,FALSE)) -> 2857000 | AQ13: =AI13 -> 2857000 | AU13: =IF($C13="","",VLOOKUP($C13,'분양가테이블(부가세기입X)'!$A$6:$AF$400,18,FALSE)) -> 28570000
E14: =IF($C14="","",VLOOKUP($C14,'분양가테이블(부가세기입X)'!$A$6:$AF$400,2,FALSE)) | I14: =IF($C14="","",VLOOKUP($C14,'분양가테이블(부가세기입X)'!$A$6:$AF$400,3,FALSE)) | K14: =IF($C14="","",VLOOKUP($C14,'분양가테이블(부가세기입X)'!$A$6:$AF$400,4,FALSE)) | M14: =IF($C14="","",VLOOKUP($C14,'분양가테이블(부가세기입X)'!$A$6:$AF$400,5,FALSE)) | O14: =IF($C14="","",VLOOKUP($C14,'분양가테이블(부가세기입X)'!$A$6:$AF$400,12,FALSE)) | Q14: =IF($C14="","",VLOOKUP($C14,'분양가테이블(부가세기입X)'!$A$6:$AF$400,13,FALSE)) | S14: =IF($C14="","",VLOOKUP($C14,'분양가테이블(부가세기입X)'!$A$6:$AF$400,6,FALSE)) | U14: =IF($C14="","",VLOOKUP($C14,'분양가테이블(부가세기입X)'!$A$6:$AF$400,7,FALSE)) | W14: =IF($C14="","",VLOOKUP($C14,'분양가테이블(부가세기입X)'!$A$6:$AF$400,17,FALSE)) | AA14: =IF($C14="","",VLOOKUP($C14,'분양가테이블(부가세기입X)'!$A$6:$AF$400,23,FALSE)) | AE14: =IF($C14="","",VLOOKUP($C14,'분양가테이블(부가세기입X)'!$A$6:$AF$400,24,FALSE)) | AI14: =IF($C14="","",VLOOKUP($C14,'분양가테이블(부가세기입X)'!$A$6:$AF$400,26,FALSE)) | AQ14: =AI14 | AU14: =IF($C14="","",VLOOKUP($C14,'분양가테이블(부가세기입X)'!$A$6:$AF$400,18,FALSE))
E15: =IF($C15="","",VLOOKUP($C15,'분양가테이블(부가세기입X)'!$A$6:$AF$400,2,FALSE)) | I15: =IF($C15="","",VLOOKUP($C15,'분양가테이블(부가세기입X)'!$A$6:$AF$400,3,FALSE)) | K15: =IF($C15="","",VLOOKUP($C15,'분양가테이블(부가세기입X)'!$A$6:$AF$400,4,FALSE)) | M15: =IF($C15="","",VLOOKUP($C15,'분양가테이블(부가세기입X)'!$A$6:$AF$400,5,FALSE)) | O15: =IF($C15="","",VLOOKUP($C15,'분양가테이블(부가세기입X)'!$A$6:$AF$400,12,FALSE)) | Q15: =IF($C15="","",VLOOKUP($C15,'분양가테이블(부가세기입X)'!$A$6:$AF$400,13,FALSE)) | S15: =IF($C15="","",VLOOKUP($C15,'분양가테이블(부가세기입X)'!$A$6:$AF$400,6,FALSE)) | U15: =IF($C15="","",VLOOKUP($C15,'분양가테이블(부가세기입X)'!$A$6:$AF$400,7,FALSE)) | W15: =IF($C15="","",VLOOKUP($C15,'분양가테이블(부가세기입X)'!$A$6:$AF$400,17,FALSE)) | AA15: =IF($C15="","",VLOOKUP($C15,'분양가테이블(부가세기입X)'!$A$6:$AF$400,23,FALSE)) | AE15: =IF($C15="","",VLOOKUP($C15,'분양가테이블(부가세기입X)'!$A$6:$AF$400,24,FALSE)) | AI15: =IF($C15="","",VLOOKUP($C15,'분양가테이블(부가세기입X)'!$A$6:$AF$400,26,FALSE)) | AQ15: =AI15 | AU15: =IF($C15="","",VLOOKUP($C15,'분양가테이블(부가세기입X)'!$A$6:$AF$400,18,FALSE))
E16: =IF($C16="","",VLOOKUP($C16,'분양가테이블(부가세기입X)'!$A$6:$AF$400,2,FALSE)) | I16: =IF($C16="","",VLOOKUP($C16,'분양가테이블(부가세기입X)'!$A$6:$AF$400,3,FALSE)) | K16: =IF($C16="","",VLOOKUP($C16,'분양가테이블(부가세기입X)'!$A$6:$AF$400,4,FALSE)) | M16: =IF($C16="","",VLOOKUP($C16,'분양가테이블(부가세기입X)'!$A$6:$AF$400,5,FALSE)) | O16: =IF($C16="","",VLOOKUP($C16,'분양가테이블(부가세기입X)'!$A$6:$AF$400,12,FALSE)) | Q16: =IF($C16="","",VLOOKUP($C16,'분양가테이블(부가세기입X)'!$A$6:$AF$400,13,FALSE)) | S16: =IF($C16="","",VLOOKUP($C16,'분양가테이블(부가세기입X)'!$A$6:$AF$400,6,FALSE)) | U16: =IF($C16="","",VLOOKUP($C16,'분양가테이블(부가세기입X)'!$A$6:$AF$400,7,FALSE)) | W16: =IF($C16="","",VLOOKUP($C16,'분양가테이블(부가세기입X)'!$A$6:$AF$400,17,FALSE)) | AA16: =IF($C16="","",VLOOKUP($C16,'분양가테이블(부가세기입X)'!$A$6:$AF$400,23,FALSE)) | AE16: =IF($C16="","",VLOOKUP($C16,'분양가테이블(부가세기입X)'!$A$6:$AF$400,24,FALSE)) | AI16: =IF($C16="","",VLOOKUP($C16,'분양가테이블(부가세기입X)'!$A$6:$AF$400,26,FALSE)) | AQ16: =AI16 | AU16: =IF($C16="","",VLOOKUP($C16,'분양가테이블(부가세기입X)'!$A$6:$AF$400,18,FALSE))
E17: =IF($C17="","",VLOOKUP($C17,'분양가테이블(부가세기입X)'!$A$6:$AF$400,2,FALSE)) | I17: =IF($C17="","",VLOOKUP($C17,'분양가테이블(부가세기입X)'!$A$6:$AF$400,3,FALSE)) | K17: =IF($C17="","",VLOOKUP($C17,'분양가테이블(부가세기입X)'!$A$6:$AF$400,4,FALSE)) | M17: =IF($C17="","",VLOOKUP($C17,'분양가테이블(부가세기입X)'!$A$6:$AF$400,5,FALSE)) | O17: =IF($C17="","",VLOOKUP($C17,'분양가테이블(부가세기입X)'!$A$6:$AF$400,12,FALSE)) | Q17: =IF($C17="","",VLOOKUP($C17,'분양가테이블(부가세기입X)'!$A$6:$AF$400,13,FALSE)) | S17: =IF($C17="","",VLOOKUP($C17,'분양가테이블(부가세기입X)'!$A$6:$AF$400,6,FALSE)) | U17: =IF($C17="","",VLOOKUP($C17,'분양가테이블(부가세기입X)'!$A$6:$AF$400,7,FALSE)) | W17: =IF($C17="","",VLOOKUP($C17,'분양가테이블(부가세기입X)'!$A$6:$AF$400,17,FALSE)) | AA17: =IF($C17="","",VLOOKUP($C17,'분양가테이블(부가세기입X)'!$A$6:$AF$400,23,FALSE)) | AE17: =IF($C17="","",VLOOKUP($C17,'분양가테이블(부가세기입X)'!$A$6:$AF$400,24,FALSE)) | AI17: =IF($C17="","",VLOOKUP($C17,'분양가테이블(부가세기입X)'!$A$6:$AF$400,26,FALSE)) | AQ17: =AI17 | AU17: =IF($C17="","",VLOOKUP($C17,'분양가테이블(부가세기입X)'!$A$6:$AF$400,18,FALSE))
E18: =IF($C18="","",VLOOKUP($C18,'분양가테이블(부가세기입X)'!$A$6:$AF$400,2,FALSE)) | I18: =IF($C18="","",VLOOKUP($C18,'분양가테이블(부가세기입X)'!$A$6:$AF$400,3,FALSE)) | K18: =IF($C18="","",VLOOKUP($C18,'분양가테이블(부가세기입X)'!$A$6:$AF$400,4,FALSE)) | M18: =IF($C18="","",VLOOKUP($C18,'분양가테이블(부가세기입X)'!$A$6:$AF$400,5,FALSE)) | O18: =IF($C18="","",VLOOKUP($C18,'분양가테이블(부가세기입X)'!$A$6:$AF$400,12,FALSE)) | Q18: =IF($C18="","",VLOOKUP($C18,'분양가테이블(부가세기입X)'!$A$6:$AF$400,13,FALSE)) | S18: =IF($C18="","",VLOOKUP($C18,'분양가테이블(부가세기입X)'!$A$6:$AF$400,6,FALSE)) | U18: =IF($C18="","",VLOOKUP($C18,'분양가테이블(부가세기입X)'!$A$6:$AF$400,7,FALSE)) | W18: =IF($C18="","",VLOOKUP($C18,'분양가테이블(부가세기입X)'!$A$6:$AF$400,17,FALSE)) | AA18: =IF($C18="","",VLOOKUP($C18,'분양가테이블(부가세기입X)'!$A$6:$AF$400,23,FALSE)) | AE18: =IF($C18="","",VLOOKUP($C18,'분양가테이블(부가세기입X)'!$A$6:$AF$400,24,FALSE)) | AI18: =IF($C18="","",VLOOKUP($C18,'분양가테이블(부가세기입X)'!$A$6:$AF$400,26,FALSE)) | AQ18: =AI18 | AU18: =IF($C18="","",VLOOKUP($C18,'분양가테이블(부가세기입X)'!$A$6:$AF$400,18,FALSE))
E19: =IF($C19="","",VLOOKUP($C19,'분양가테이블(부가세기입X)'!$A$6:$AF$400,2,FALSE)) | I19: =IF($C19="","",VLOOKUP($C19,'분양가테이블(부가세기입X)'!$A$6:$AF$400,3,FALSE)) | K19: =IF($C19="","",VLOOKUP($C19,'분양가테이블(부가세기입X)'!$A$6:$AF$400,4,FALSE)) | M19: =IF($C19="","",VLOOKUP($C19,'분양가테이블(부가세기입X)'!$A$6:$AF$400,5,FALSE)) | O19: =IF($C19="","",VLOOKUP($C19,'분양가테이블(부가세기입X)'!$A$6:$AF$400,12,FALSE)) | Q19: =IF($C19="","",VLOOKUP($C19,'분양가테이블(부가세기입X)'!$A$6:$AF$400,13,FALSE)) | S19: =IF($C19="","",VLOOKUP($C19,'분양가테이블(부가세기입X)'!$A$6:$AF$400,6,FALSE)) | U19: =IF($C19="","",VLOOKUP($C19,'분양가테이블(부가세기입X)'!$A$6:$AF$400,7,FALSE)) | W19: =IF($C19="","",VLOOKUP($C19,'분양가테이블(부가세기입X)'!$A$6:$AF$400,17,FALSE)) | AA19: =IF($C19="","",VLOOKUP($C19,'분양가테이블(부가세기입X)'!$A$6:$AF$400,23,FALSE)) | AE19: =IF($C19="","",VLOOKUP($C19,'분양가테이블(부가세기입X)'!$A$6:$AF$400,24,FALSE)) | AI19: =IF($C19="","",VLOOKUP($C19,'분양가테이블(부가세기입X)'!$A$6:$AF$400,26,FALSE)) | AQ19: =AI19 | AU19: =IF($C19="","",VLOOKUP($C19,'분양가테이블(부가세기입X)'!$A$6:$AF$400,18,FALSE))
E20: =IF($C20="","",VLOOKUP($C20,'분양가테이블(부가세기입X)'!$A$6:$AF$400,2,FALSE)) | I20: =IF($C20="","",VLOOKUP($C20,'분양가테이블(부가세기입X)'!$A$6:$AF$400,3,FALSE)) | K20: =IF($C20="","",VLOOKUP($C20,'분양가테이블(부가세기입X)'!$A$6:$AF$400,4,FALSE)) | M20: =IF($C20="","",VLOOKUP($C20,'분양가테이블(부가세기입X)'!$A$6:$AF$400,5,FALSE)) | O20: =IF($C20="","",VLOOKUP($C20,'분양가테이블(부가세기입X)'!$A$6:$AF$400,12,FALSE)) | Q20: =IF($C20="","",VLOOKUP($C20,'분양가테이블(부가세기입X)'!$A$6:$AF$400,13,FALSE)) | S20: =IF($C20="","",VLOOKUP($C20,'분양가테이블(부가세기입X)'!$A$6:$AF$400,6,FALSE)) | U20: =IF($C20="","",VLOOKUP($C20,'분양가테이블(부가세기입X)'!$A$6:$AF$400,7,FALSE)) | W20: =IF($C20="","",VLOOKUP($C20,'분양가테이블(부가세기입X)'!$A$6:$AF$400,17,FALSE)) | AA20: =IF($C20="","",VLOOKUP($C20,'분양가테이블(부가세기입X)'!$A$6:$AF$400,23,FALSE)) | AE20: =IF($C20="","",VLOOKUP($C20,'분양가테이블(부가세기입X)'!$A$6:$AF$400,24,FALSE)) | AI20: =IF($C20="","",VLOOKUP($C20,'분양가테이블(부가세기입X)'!$A$6:$AF$400,26,FALSE)) | AQ20: =AI20 | AU20: =IF($C20="","",VLOOKUP($C20,'분양가테이블(부가세기입X)'!$A$6:$AF$400,18,FALSE))
E21: =IF($C21="","",VLOOKUP($C21,'분양가테이블(부가세기입X)'!$A$6:$AF$400,2,FALSE)) | I21: =IF($C21="","",VLOOKUP($C21,'분양가테이블(부가세기입X)'!$A$6:$AF$400,3,FALSE)) | K21: =IF($C21="","",VLOOKUP($C21,'분양가테이블(부가세기입X)'!$A$6:$AF$400,4,FALSE)) | M21: =IF($C21="","",VLOOKUP($C21,'분양가테이블(부가세기입X)'!$A$6:$AF$400,5,FALSE)) | O21: =IF($C21="","",VLOOKUP($C21,'분양가테이블(부가세기입X)'!$A$6:$AF$400,12,FALSE)) | Q21: =IF($C21="","",VLOOKUP($C21,'분양가테이블(부가세기입X)'!$A$6:$AF$400,13,FALSE)) | S21: =IF($C21="","",VLOOKUP($C21,'분양가테이블(부가세기입X)'!$A$6:$AF$400,6,FALSE)) | U21: =IF($C21="","",VLOOKUP($C21,'분양가테이블(부가세기입X)'!$A$6:$AF$400,7,FALSE)) | W21: =IF($C21="","",VLOOKUP($C21,'분양가테이블(부가세기입X)'!$A$6:$AF$400,17,FALSE)) | AA21: =IF($C21="","",VLOOKUP($C21,'분양가테이블(부가세기입X)'!$A$6:$AF$400,23,FALSE)) | AE21: =IF($C21="","",VLOOKUP($C21,'분양가테이블(부가세기입X)'!$A$6:$AF$400,24,FALSE)) | AI21: =IF($C21="","",VLOOKUP($C21,'분양가테이블(부가세기입X)'!$A$6:$AF$400,26,FALSE)) | AQ21: =AI21 | AU21: =IF($C21="","",VLOOKUP($C21,'분양가테이블(부가세기입X)'!$A$6:$AF$400,18,FALSE))
E22: =IF($C22="","",VLOOKUP($C22,'분양가테이블(부가세기입X)'!$A$6:$AF$400,2,FALSE)) | I22: =IF($C22="","",VLOOKUP($C22,'분양가테이블(부가세기입X)'!$A$6:$AF$400,3,FALSE)) | K22: =IF($C22="","",VLOOKUP($C22,'분양가테이블(부가세기입X)'!$A$6:$AF$400,4,FALSE)) | M22: =IF($C22="","",VLOOKUP($C22,'분양가테이블(부가세기입X)'!$A$6:$AF$400,5,FALSE)) | O22: =IF($C22="","",VLOOKUP($C22,'분양가테이블(부가세기입X)'!$A$6:$AF$400,12,FALSE)) | Q22: =IF($C22="","",VLOOKUP($C22,'분양가테이블(부가세기입X)'!$A$6:$AF$400,13,FALSE)) | S22: =IF($C22="","",VLOOKUP($C22,'분양가테이블(부가세기입X)'!$A$6:$AF$400,6,FALSE)) | U22: =IF($C22="","",VLOOKUP($C22,'분양가테이블(부가세기입X)'!$A$6:$AF$400,7,FALSE)) | W22: =IF($C22="","",VLOOKUP($C22,'분양가테이블(부가세기입X)'!$A$6:$AF$400,17,FALSE)) | AA22: =IF($C22="","",VLOOKUP($C22,'분양가테이블(부가세기입X)'!$A$6:$AF$400,23,FALSE)) | AE22: =IF($C22="","",VLOOKUP($C22,'분양가테이블(부가세기입X)'!$A$6:$AF$400,24,FALSE)) | AI22: =IF($C22="","",VLOOKUP($C22,'분양가테이블(부가세기입X)'!$A$6:$AF$400,26,FALSE)) | AQ22: =AI22 | AU22: =IF($C22="","",VLOOKUP($C22,'분양가테이블(부가세기입X)'!$A$6:$AF$400,18,FALSE))
E23: =IF($C23="","",VLOOKUP($C23,'분양가테이블(부가세기입X)'!$A$6:$AF$400,2,FALSE)) | I23: =IF($C23="","",VLOOKUP($C23,'분양가테이블(부가세기입X)'!$A$6:$AF$400,3,FALSE)) | K23: =IF($C23="","",VLOOKUP($C23,'분양가테이블(부가세기입X)'!$A$6:$AF$400,4,FALSE)) | M23: =IF($C23="","",VLOOKUP($C23,'분양가테이블(부가세기입X)'!$A$6:$AF$400,5,FALSE)) | O23: =IF($C23="","",VLOOKUP($C23,'분양가테이블(부가세기입X)'!$A$6:$AF$400,12,FALSE)) | Q23: =IF($C23="","",VLOOKUP($C23,'분양가테이블(부가세기입X)'!$A$6:$AF$400,13,FALSE)) | S23: =IF($C23="","",VLOOKUP($C23,'분양가테이블(부가세기입X)'!$A$6:$AF$400,6,FALSE)) | U23: =IF($C23="","",VLOOKUP($C23,'분양가테이블(부가세기입X)'!$A$6:$AF$400,7,FALSE)) | W23: =IF($C23="","",VLOOKUP($C23,'분양가테이블(부가세기입X)'!$A$6:$AF$400,17,FALSE)) | AA23: =IF($C23="","",VLOOKUP($C23,'분양가테이블(부가세기입X)'!$A$6:$AF$400,23,FALSE)) | AE23: =IF($C23="","",VLOOKUP($C23,'분양가테이블(부가세기입X)'!$A$6:$AF$400,24,FALSE)) | AI23: =IF($C23="","",VLOOKUP($C23,'분양가테이블(부가세기입X)'!$A$6:$AF$400,26,FALSE)) | AQ23: =AI23 | AU23: =IF($C23="","",VLOOKUP($C23,'분양가테이블(부가세기입X)'!$A$6:$AF$400,18,FALSE))
E24: =IF($C24="","",VLOOKUP($C24,'분양가테이블(부가세기입X)'!$A$6:$AF$400,2,FALSE)) | I24: =IF($C24="","",VLOOKUP($C24,'분양가테이블(부가세기입X)'!$A$6:$AF$400,3,FALSE)) | K24: =IF($C24="","",VLOOKUP($C24,'분양가테이블(부가세기입X)'!$A$6:$AF$400,4,FALSE)) | M24: =IF($C24="","",VLOOKUP($C24,'분양가테이블(부가세기입X)'!$A$6:$AF$400,5,FALSE)) | O24: =IF($C24="","",VLOOKUP($C24,'분양가테이블(부가세기입X)'!$A$6:$AF$400,12,FALSE)) | Q24: =IF($C24="","",VLOOKUP($C24,'분양가테이블(부가세기입X)'!$A$6:$AF$400,13,FALSE)) | S24: =IF($C24="","",VLOOKUP($C24,'분양가테이블(부가세기입X)'!$A$6:$AF$400,6,FALSE)) | U24: =IF($C24="","",VLOOKUP($C24,'분양가테이블(부가세기입X)'!$A$6:$AF$400,7,FALSE)) | W24: =IF($C24="","",VLOOKUP($C24,'분양가테이블(부가세기입X)'!$A$6:$AF$400,17,FALSE)) | AA24: =IF($C24="","",VLOOKUP($C24,'분양가테이블(부가세기입X)'!$A$6:$AF$400,23,FALSE)) | AE24: =IF($C24="","",VLOOKUP($C24,'분양가테이블(부가세기입X)'!$A$6:$AF$400,24,FALSE)) | AI24: =IF($C24="","",VLOOKUP($C24,'분양가테이블(부가세기입X)'!$A$6:$AF$400,26,FALSE)) | AQ24: =AI24 | AU24: =IF($C24="","",VLOOKUP($C24,'분양가테이블(부가세기입X)'!$A$6:$AF$400,18,FALSE))
E25: =IF($C25="","",VLOOKUP($C25,'분양가테이블(부가세기입X)'!$A$6:$AF$400,2,FALSE)) | I25: =IF($C25="","",VLOOKUP($C25,'분양가테이블(부가세기입X)'!$A$6:$AF$400,3,FALSE)) | K25: =IF($C25="","",VLOOKUP($C25,'분양가테이블(부가세기입X)'!$A$6:$AF$400,4,FALSE)) | M25: =IF($C25="","",VLOOKUP($C25,'분양가테이블(부가세기입X)'!$A$6:$AF$400,5,FALSE)) | O25: =IF($C25="","",VLOOKUP($C25,'분양가테이블(부가세기입X)'!$A$6:$AF$400,12,FALSE)) | Q25: =IF($C25="","",VLOOKUP($C25,'분양가테이블(부가세기입X)'!$A$6:$AF$400,13,FALSE)) | S25: =IF($C25="","",VLOOKUP($C25,'분양가테이블(부가세기입X)'!$A$6:$AF$400,6,FALSE)) | U25: =IF($C25="","",VLOOKUP($C25,'분양가테이블(부가세기입X)'!$A$6:$AF$400,7,FALSE)) | W25: =IF($C25="","",VLOOKUP($C25,'분양가테이블(부가세기입X)'!$A$6:$AF$400,17,FALSE)) | AA25: =IF($C25="","",VLOOKUP($C25,'분양가테이블(부가세기입X)'!$A$6:$AF$400,23,FALSE)) | AE25: =IF($C25="","",VLOOKUP($C25,'분양가테이블(부가세기입X)'!$A$6:$AF$400,24,FALSE)) | AI25: =IF($C25="","",VLOOKUP($C25,'분양가테이블(부가세기입X)'!$A$6:$AF$400,26,FALSE)) | AQ25: =AI25 | AU25: =IF($C25="","",VLOOKUP($C25,'분양가테이블(부가세기입X)'!$A$6:$AF$400,18,FALSE))
... E34: =IF($C34="","",VLOOKUP($C34,'분양가테이블(부가세기입X)'!$A$6:$AF$400,2,FALSE)) | I34: =IF($C34="","",VLOOKUP($C34,'분양가테이블(부가세기입X)'!$A$6:$AF$400,3,FALSE)) | K34: =IF($C34="","",VLOOKUP($C34,'분양가테이블(부가세기입X)'!$A$6:$AF$400,4,FALSE)) | M34: =IF($C34="","",VLOOKUP($C34,'분양가테이블(부가세기입X)'!$A$6:$AF$400,5,FALSE)) | O34: =IF($C34="","",VLOOKUP($C34,'분양가테이블(부가세기입X)'!$A$6:$AF$400,12,FALSE)) | Q34: =IF($C34="","",VLOOKUP($C34,'분양가테이블(부가세기입X)'!$A$6:$AF$400,13,FALSE)) | S34: =IF($C34="","",VLOOKUP($C34,'분양가테이블(부가세기입X)'!$A$6:$AF$400,6,FALSE)) | U34: =IF($C34="","",VLOOKUP($C34,'분양가테이블(부가세기입X)'!$A$6:$AF$400,7,FALSE)) | W34: =IF($C34="","",VLOOKUP($C34,'분양가테이블(부가세기입X)'!$A$6:$AF$400,17,FALSE)) | AA34: =IF($C34="","",VLOOKUP($C34,'분양가테이블(부가세기입X)'!$A$6:$AF$400,23,FALSE)) | AE34: =IF($C34="","",VLOOKUP($C34,'분양가테이블(부가세기입X)'!$A$6:$AF$400,24,FALSE)) | AI34: =IF($C34="","",VLOOKUP($C34,'분양가테이블(부가세기입X)'!$A$6:$AF$400,26,FALSE)) | AQ34: =AI34 | AU34: =IF($C34="","",VLOOKUP($C34,'분양가테이블(부가세기입X)'!$A$6:$AF$400,18,FALSE))
C35: 합 계 | K35: =SUM(K10:L34) -> 245.07 | M35: =SUM(M10:N34) -> 74.133675 | O35: =SUM(O10:P34) -> 289.59 | Q35: =SUM(Q10:R34) -> 87.600975 | S35: =SUM(S10:T34) -> 534.66 | U35: =SUM(U10:V34) -> 161.73465 | W35: =SUM(W10:Z34) -> 8571000 | AA35: =SUM(AA10:AD34) -> 857100 | AE35: =SUM(AE10:AH34) -> 9428100 | AI35: =SUM(AI10:AL34) -> 8571000 | AM35: =SUM(AM10:AP34) -> 0 | AQ35: =SUM(AQ10:AT34) -> 8571000 | AU35: =SUM(AU10:AX34) -> 85710000
C37: 2. 납부조건 (분양호실에 해당) | V37: [단위: 원] | AB37: 3. 납부조건 (임대호실에 해당) | AU37: [단위: 원]
C38: 구분 | G38: 비율 | I38: 납부일자 | M38: 공급가액 | Q38: 부가세 | U38: 총 분양가 | AB38: 구분 | AF38: 비율 | AH38: 납부일자 | AL38: 보증금 | AQ38: 임대가 | AU38: 비고
C39: 계약금 | G39: 0.1 | I39: 계약일 | M39: - | Q39: - | U39: - | AB39: 계약보증금 | AF39: 1 | AH39: - | AL39: =AU35 -> 85710000 | AQ39: =W35 -> 8571000
C40: 중도금 | G40: - | I40: - | M40: - | Q40: - | U40: - | AB40: 계약금 | AF40: 0.1 | AH40: 계약일 | AL40: =AL39*10% -> 8571000
C41: 잔금 | G41: 0.9 | I41: 입주지정일 | M41: - | Q41: - | U41: - | AB41: 중도금 | AF41: - | AH41: 해당없음
C42: 합계 | G42: 1 | I42: - | M42: - | Q42: =AA15 | U42: =AE15 | AB42: 잔금 | AF42: 0.9 | AH42: 입주지정일 | AL42: =AL39-AL40 -> 77139000
C44: 4. 계약금 입금계좌 | W44: 5. 계약시 구비서류
C45: 은행명 | G45: 계좌번호 | P45: 예금주 | W45: 개인 | AB45: 인감증명서 1부, 주민등록등본 1부, 신분증 사본(복사), 개인인감도장
C46: IBK기업은행 | G46: 694-022383-01-030 | P46: 신한자산신탁주식회사
W47: 개인 사업자 | AB47: 인감증명서 1부, 주민등록등본 1부, 대표자 신분증 사본(복사), 사업자등록증 1부, 개인 인감도장
C48: 입금 표기 예시 (필독)
C49: 호실+계약자명or상호명 = (예시) 101호 홍길동 / 101호 홍길동산업 | W49: 법인 사업자 | AB49: 법인인감증명서 1부, 법인등기부등본 1부, 대표자 신분증 사본(복사), 사업자등록증 1부, 법인 인감도장
C51: ※ 계약금 입금 전 계좌번호 확인 후 담당자에게 연락하여 입금하시길 바랍니다. | W51: ※ 대리인 계약시: 상기 구비서류 외 위임장 1부, 계약자 인감증명서(위임용) 2부, 대리인 신분증 필수

Sheet 견적서사용법
BB1: *필독사항
BB2: 1. 호실 외 면적 및 금액, 용도 납부일자 비율등의 수치를 변경하지 말 것.
BB3: 2. 견적서의 내용 중 특이사항이나 문제가 될 내용이 있을 시엔 유케이아이디로 문의 부탁드립니다.
AT5: 작성일: | AV5: =TODAY() -> 45860
C6: 1. 분양호실 견적서 | AU6: [단위: 원]
C7: 호실 | E7: 용도 | K7: 면적 | W7: 공급가액 (VAT 별도) | AA7: 부가세 | AE7: 총 분양가 (VAT 포함) | AI7: 계약금 | AM7: 납입금 | AU7: 비고
K8: 전용면적 | O8: 공용면적 | S8: 분양면적 | AI8: 0.1 | AM8: 청약 납입금 | AQ8: 계약 납입금
K9: ㎡ | M9: 평 | O9: ㎡ | Q9: 평 | S9: ㎡ | U9: 평 | AI9: A | AM9: B | AQ9: C
C10: 301 | E10: =IF($C10="","",VLOOKUP($C10,'분양가테이블(부가세기입X)'!A:T,2,FALSE)) -> #N/A | I10: =IF($C10="","",VLOOKUP($C10,'분양가테이블(부가세기입X)'!A:T,3,FALSE)) -> #N/A | K10: =IF($C10="","",VLOOKUP($C10,'분양가테이블(부가세기입X)'!A:T,4,FALSE)) -> #N/A | M10: =IF($C10="","",VLOOKUP($C10,'분양가테이블(부가세기입X)'!A:T,5,FALSE)) -> #N/A | O10: =IF($C10="","",VLOOKUP($C10,'분양가테이블(부가세기입X)'!A:T,8,FALSE)) -> #N/A | Q10: =IF($C10="","",VLOOKUP($C10,'분양가테이블(부가세기입X)'!A:T,9,FALSE)) -> #N/A | S10: =IF($C10="","",VLOOKUP($C10,'분양가테이블(부가세기입X)'!A:T,6,FALSE)) -> #N/A | U10: =IF($C10="","",VLOOKUP($C10,'분양가테이블(부가세기입X)'!A:T,7,FALSE)) -> #N/A | W10: =IF($C10="","",VLOOKUP($C10,'분양가테이블(부가세기입X)'!A:T,12,FALSE)) -> #N/A | AI10: =AE10*10% -> 0 | AM10: 10000000 | AQ10: =AI10-AM10 -> -10000000
C11: 201 | E11: =IF($C11="","",VLOOKUP($C11,'분양가테이블(부가세기입X)'!A:T,2,FALSE)) -> #N/A | I11: =IF($C11="","",VLOOKUP($C11,'분양가테이블(부가세기입X)'!A:T,3,FALSE)) -> #N/A | K11: =IF($C11="","",VLOOKUP($C11,'분양가테이블(부가세기입X)'!A:T,4,FALSE)) -> #N/A | M11: =IF($C11="","",VLOOKUP($C11,'분양가테이블(부가세기입X)'!A:T,5,FALSE)) -> #N/A | O11: =IF($C11="","",VLOOKUP($C11,'분양가테이블(부가세기입X)'!A:T,8,FALSE)) -> #N/A | Q11: =IF($C11="","",VLOOKUP($C11,'분양가테이블(부가세기입X)'!A:T,9,FALSE)) -> #N/A | S11: =IF($C11="","",VLOOKUP($C11,'분양가테이블(부가세기입X)'!A:T,6,FALSE)) -> #N/A | U11: =IF($C11="","",VLOOKUP($C11,'분양가테이블(부가세기입X)'!A:T,7,FALSE)) -> #N/A | W11: =IF($C11="","",VLOOKUP($C11,'분양가테이블(부가세기입X)'!A:T,12,FALSE)) -> #N/A | AI11: =AE11*10% -> 0 | AQ11: =AI11-AM11 -> 0
C12: 311 | E12: =IF($C12="","",VLOOKUP($C12,'분양가테이블(부가세기입X)'!A:T,2,FALSE)) -> #N/A | I12: =IF($C12="","",VLOOKUP($C12,'분양가테이블(부가세기입X)'!A:T,3,FALSE)) -> #N/A | K12: =IF($C12="","",VLOOKUP($C12,'분양가테이블(부가세기입X)'!A:T,4,FALSE)) -> #N/A | M12: =IF($C12="","",VLOOKUP($C12,'분양가테이블(부가세기입X)'!A:T,5,FALSE)) -> #N/A | O12: =IF($C12="","",VLOOKUP($C12,'분양가테이블(부가세기입X)'!A:T,8,FALSE)) -> #N/A | Q12: =IF($C12="","",VLOOKUP($C12,'분양가테이블(부가세기입X)'!A:T,9,FALSE)) -> #N/A | S12: =IF($C12="","",VLOOKUP($C12,'분양가테이블(부가세기입X)'!A:T,6,FALSE)) -> #N/A | U12: =IF($C12="","",VLOOKUP($C12,'분양가테이블(부가세기입X)'!A:T,7,FALSE)) -> #N/A | W12: =IF($C12="","",VLOOKUP($C12,'분양가테이블(부가세기입X)'!A:T,12,FALSE)) -> #N/A | AI12: =AE12*10% -> 0 | AQ12: =AI12-AM12 -> 0
C13: 311 | E13: =IF($C13="","",VLOOKUP($C13,'분양가테이블(부가세기입X)'!A:T,2,FALSE)) -> #N/A | I13: =IF($C13="","",VLOOKUP($C13,'분양가테이블(부가세기입X)'!A:T,3,FALSE)) -> #N/A | K13: =IF($C13="","",VLOOKUP($C13,'분양가테이블(부가세기입X)'!A:T,4,FALSE)) -> #N/A | M13: =IF($C13="","",VLOOKUP($C13,'분양가테이블(부가세기입X)'!A:T,5,FALSE)) -> #N/A | O13: =IF($C13="","",VLOOKUP($C13,'분양가테이블(부가세기입X)'!A:T,8,FALSE)) -> #N/A | Q13: =IF($C13="","",VLOOKUP($C13,'분양가테이블(부가세기입X)'!A:T,9,FALSE)) -> #N/A | S13: =IF($C13="","",VLOOKUP($C13,'분양가테이블(부가세기입X)'!A:T,6,FALSE)) -> #N/A | U13: =IF($C13="","",VLOOKUP($C13,'분양가테이블(부가세기입X)'!A:T,7,FALSE)) -> #N/A | W13: =IF($C13="","",VLOOKUP($C13,'분양가테이블(부가세기입X)'!A:T,12,FALSE)) -> #N/A | AI13: =AE13*10% -> 0 | AQ13: =AI13-AM13 -> 0
C14: 311 | E14: =IF($C14="","",VLOOKUP($C14,'분양가테이블(부가세기입X)'!A:T,2,FALSE)) -> #N/A | I14: =IF($C14="","",VLOOKUP($C14,'분양가테이블(부가세기입X)'!A:T,3,FALSE)) -> #N/A | K14: =IF($C14="","",VLOOKUP($C14,'분양가테이블(부가세기입X)'!A:T,4,FALSE)) -> #N/A | M14: =IF($C14="","",VLOOKUP($C14,'분양가테이블(부가세기입X)'!A:T,5,FALSE)) -> #N/A | O14: =IF($C14="","",VLOOKUP($C14,'분양가테이블(부가세기입X)'!A:T,8,FALSE)) -> #N/A | Q14: =IF($C14="","",VLOOKUP($C14,'분양가테이블(부가세기입X)'!A:T,9,FALSE)) -> #N/A | S14: =IF($C14="","",VLOOKUP($C14,'분양가테이블(부가세기입X)'!A:T,6,FALSE)) -> #N/A | U14: =IF($C14="","",VLOOKUP($C14,'분양가테이블(부가세기입X)'!A:T,7,FALSE)) -> #N/A | W14: =IF($C14="","",VLOOKUP($C14,'분양가테이블(부가세기입X)'!A:T,12,FALSE)) -> #N/A | AI14: =AE14*10% -> 0 | AQ14: =AI14-AM14 -> 0
C15: 합계 | K15: =SUM(K10:L14) -> #N/A | M15: =SUM(M10:N14) -> #N/A | O15: =SUM(O10:P14) -> #N/A | Q15: =SUM(Q10:R14) -> #N/A | S15: =SUM(S10:T14) -> #N/A | U15: =SUM(U10:V14) -> #N/A | W15: =SUM(W10:Z14) -> #N/A | AA15: =SUM(AA10:AD14) -> 0 | AE15: =SUM(AE10:AH14) -> 0 | AI15: =SUM(AI10:AL14) -> 0 | AM15: =SUM(AM10:AP14) -> 10000000 | AQ15: =SUM(AQ10:AT14) -> -10000000 | AU15: -
C17: 2. 임대호실 견적서 | AU17: [단위: 원]
C18: 호실 | E18: 용도 | K18: 면적 | W18: 공급가액 | AA18: 부가세 | AE18: 총 분양가 | AI18: 계약금 | AM18: 납입금 | AU18: 비고
K19: 전용면적 | O19: 공용면적 | S19: 분양면적 | AI19: 0.1 | AM19: 청약 납입금 | AQ19: 계약 납입금
K20: ㎡ | M20: 평 | O20: ㎡ | Q20: 평 | S20: ㎡ | U20: 평 | AI20: A | AM20: B | AQ20: C
C21: 210 | E21: =IF($C21="","",VLOOKUP($C21,'분양가테이블(부가세기입X)'!A:T,2,FALSE)) -> #N/A | I21: =IF($C21="","",VLOOKUP($C21,'분양가테이블(부가세기입X)'!A:T,3,FALSE)) -> #N/A | K21: =IF($C21="","",VLOOKUP($C21,'분양가테이블(부가세기입X)'!A:T,4,FALSE)) -> #N/A | M21: =IF($C21="","",VLOOKUP($C21,'분양가테이블(부가세기입X)'!A:T,5,FALSE)) -> #N/A | O21: =IF($C21="","",VLOOKUP($C21,'분양가테이블(부가세기입X)'!A:T,8,FALSE)) -> #N/A | Q21: =IF($C21="","",VLOOKUP($C21,'분양가테이블(부가세기입X)'!A:T,9,FALSE)) -> #N/A | S21: =IF($C21="","",VLOOKUP($C21,'분양가테이블(부가세기입X)'!A:T,6,FALSE)) -> #N/A | U21: =IF($C21="","",VLOOKUP($C21,'분양가테이블(부가세기입X)'!A:T,7,FALSE)) -> #N/A | W21: =IF($C21="","",VLOOKUP($C21,'분양가테이블(부가세기입X)'!A:T,12,FALSE)) -> #N/A | AI21: =AE21*10% -> 0 | AQ21: =AI21-AM21 -> 0
C22: 311 | E22: =IF($C22="","",VLOOKUP($C22,'분양가테이블(부가세기입X)'!A:T,2,FALSE)) -> #N/A | I22: =IF($C22="","",VLOOKUP($C22,'분양가테이블(부가세기입X)'!A:T,3,FALSE)) -> #N/A | K22: =IF($C22="","",VLOOKUP($C22,'분양가테이블(부가세기입X)'!A:T,4,FALSE)) -> #N/A | M22: =IF($C11="","",VLOOKUP($C11,'분양가테이블(부가세기입X)'!A:T,5,FALSE)) -> #N/A | O22: =IF($C22="","",VLOOKUP($C22,'분양가테이블(부가세기입X)'!A:T,8,FALSE)) -> #N/A | Q22: =IF($C22="","",VLOOKUP($C22,'분양가테이블(부가세기입X)'!A:T,9,FALSE)) -> #N/A | S22: =IF($C22="","",VLOOKUP($C22,'분양가테이블(부가세기입X)'!A:T,6,FALSE)) -> #N/A | U22: =IF($C22="","",VLOOKUP($C22,'분양가테이블(부가세기입X)'!A:T,7,FALSE)) -> #N/A | W22: =IF($C22="","",VLOOKUP($C22,'분양가테이블(부가세기입X)'!A:T,12,FALSE)) -> #N/A | AI22: =AE22*10% -> 0 | AQ22: =AI22-AM22 -> 0
C23: 311 | E23: =IF($C23="","",VLOOKUP($C23,'분양가테이블(부가세기입X)'!A:T,2,FALSE)) -> #N/A | I23: =IF($C23="","",VLOOKUP($C23,'분양가테이블(부가세기입X)'!A:T,3,FALSE)) -> #N/A | K23: =IF($C23="","",VLOOKUP($C23,'분양가테이블(부가세기입X)'!A:T,4,FALSE)) -> #N/A | M23: =IF($C12="","",VLOOKUP($C12,'분양가테이블(부가세기입X)'!A:T,5,FALSE)) -> #N/A | O23: =IF($C23="","",VLOOKUP($C23,'분양가테이블(부가세기입X)'!A:T,8,FALSE)) -> #N/A | Q23: =IF($C23="","",VLOOKUP($C23,'분양가테이블(부가세기입X)'!A:T,9,FALSE)) -> #N/A | S23: =IF($C23="","",VLOOKUP($C23,'분양가테이블(부가세기입X)'!A:T,6,FALSE)) -> #N/A | U23: =IF($C23="","",VLOOKUP($C23,'분양가테이블(부가세기입X)'!A:T,7,FALSE)) -> #N/A | W23: =IF($C23="","",VLOOKUP($C23,'분양가테이블(부가세기입X)'!A:T,12,FALSE)) -> #N/A | AI23: =AE23*10% -> 0 | AQ23: =AI23-AM23 -> 0
C24: 311 | E24: =IF($C24="","",VLOOKUP($C24,'분양가테이블(부가세기입X)'!A:T,2,FALSE)) -> #N/A | I24: =IF($C24="","",VLOOKUP($C24,'분양가테이블(부가세기입X)'!A:T,3,FALSE)) -> #N/A | K24: =IF($C24="","",VLOOKUP($C24,'분양가테이블(부가세기입X)'!A:T,4,FALSE)) -> #N/A | M24: =IF($C13="","",VLOOKUP($C13,'분양가테이블(부가세기입X)'!A:T,5,FALSE)) -> #N/A | O24: =IF($C24="","",VLOOKUP($C24,'분양가테이블(부가세기입X)'!A:T,8,FALSE)) -> #N/A | Q24: =IF($C24="","",VLOOKUP($C24,'분양가테이블(부가세기입X)'!A:T,9,FALSE)) -> #N/A | S24: =IF($C24="","",VLOOKUP($C24,'분양가테이블(부가세기입X)'!A:T,6,FALSE)) -> #N/A | U24: =IF($C24="","",VLOOKUP($C24,'분양가테이블(부가세기입X)'!A:T,7,FALSE)) -> #N/A | W24: =IF($C24="","",VLOOKUP($C24,'분양가테이블(부가세기입X)'!A:T,12,FALSE)) -> #N/A | AI24: =AE24*10% -> 0 | AQ24: =AI24-AM24 -> 0
C25: 311 | E25: =IF($C25="","",VLOOKUP($C25,'분양가테이블(부가세기입X)'!A:T,2,FALSE)) -> #N/A | I25: =IF($C25="","",VLOOKUP($C25,'분양가테이블(부가세기입X)'!A:T,3,FALSE)) -> #N/A | K25: =IF($C25="","",VLOOKUP($C25,'분양가테이블(부가세기입X)'!A:T,4,FALSE)) -> #N/A | M25: =IF($C14="","",VLOOKUP($C14,'분양가테이블(부가세기입X)'!A:T,5,FALSE)) -> #N/A | O25: =IF($C25="","",VLOOKUP($C25,'분양가테이블(부가세기입X)'!A:T,8,FALSE)) -> #N/A | Q25: =IF($C25="","",VLOOKUP($C25,'분양가테이블(부가세기입X)'!A:T,9,FALSE)) -> #N/A | S25: =IF($C25="","",VLOOKUP($C25,'분양가테이블(부가세기입X)'!A:T,6,FALSE)) -> #N/A | U25: =IF($C25="","",VLOOKUP($C25,'분양가테이블(부가세기입X)'!A:T,7,FALSE)) -> #N/A | W25: =IF($C25="","",VLOOKUP($C25,'분양가테이블(부가세기입X)'!A:T,12,FALSE)) -> #N/A | AI25: =AE25*10% -> 0 | AQ25: =AI25-AM25 -> 0
K26: =SUM(K21:L25) -> #N/A | M26: =SUM(M21:N25) -> #N/A | O26: =SUM(O21:P25) -> #N/A | Q26: =SUM(Q21:R25) -> #N/A | S26: =SUM(S21:T25) -> #N/A | U26: =SUM(U21:V25) -> #N/A | W26: =SUM(W21:Z25) -> #N/A | AA26: =SUM(AA21:AD25) -> 0 | AE26: =SUM(AE21:AH25) -> 0 | AI26: =SUM(AI21:AL25) -> 0 | AM26: =SUM(AM21:AP25) -> 0 | AQ26: =SUM(AQ21:AT25) -> 0 | AU26: -
C28: 3. 납부조건 (분양호실에 해당) | V28: [단위: 원] | AB28: 4. 납부조건 (임대호실에 해당) | AU28: [단위: 원]
C29: 구분 | G29: 비율 | I29: 납부일자 | M29: 공급가액 | Q29: 부가세 | U29: 총 분양가 | AB29: 구분 | AF29: 비율 | AH29: 납부일자 | AL29: 보증금 | AQ29: 임대가 | AU29: 비고
C30: 계약금 | G30: 0.1 | I30: 계약일 | M30: =W15*10% -> #N/A | Q30: =AA15*10% -> 0 | U30: =AE15*10% -> 0 | AB30: 계약보증금 | AF30: 1 | AH30: 계약일
C31: 중도금 | G31: 0.4 | I31: 약정일 | M31: =W15*40% -> #N/A | Q31: =AA15*40% -> 0 | U31: =AE15*40% -> 0 | AB31: 계약금 | AF31: 0.05 | AH31: 계약일
C32: 잔금 | G32: 0.5 | I32: 입주지정일 | M32: =W15*50% -> #N/A | Q32: =AA15*50% -> 0 | U32: =AE15*50% -> 0 | AB32: 중도금 | AF32: 0.05 | AH32: 계약일
C33: 합계 | G33: 1 | I33: - | M33: =W15 -> #N/A | Q33: =AA15 -> 0 | U33: =AE15 -> 0 | AB33: 잔금 | AF33: 0.9 | AH33: 계약일
C35: 5. 계약금 입금계좌 | W35: 6. 계약시 구비서류
C36: 은행명 | G36: 계좌번호 | P36: 예금주 | W36: 개인 | AB36: 정부수입인지 (사본제출, 원본 계약자 보관 필수) 인감증명서 3부, 주민등록등본 1부, 신분증 사본(복사), 개인인감도장
C37: ㅇㅇ은행 | G37: 0000-00-000000 | P37: ㅇㅇㅇㅇㅇㅇ(주)
W38: 개인 사업자 | AB38: 정부수입인지 (사본제출, 원본 계약자 보관 필수) 인감증명서 3부, 주민등록등본 1부, 대표자 신분증 사본(복사), 개인인감도장
C39: 입금 표기 예시 (필독)
C40: 호실+계약자명or상호명 = (예시) 101호 홍길동 / 101호 홍길동산업 | W40: 법인 사업자 | AB40: 정부수입인지 (사본제출, 원본 계약자 보관 필수) 법인인감증명서 3부, 법인등기부등본 1부, 대표자 신분증 사본(복사), 사업자등록증 1부, 법인 인감도장
C42: ※ 계약금 입금 전 계좌번호 확인 후 담당자에게 연락하여 입금하시길 바랍니다. | W42: ※ 대리인 계약시: 상기 구비서류 외 위임장 1부, 대리인 신분증 필수

Sheet 분양가테이블(부가세기입X)
T1: 0.45 | U1: 0.55
A2: 1 | B2: 2 | C2: 3 | D2: 4 | E2: 5 | F2: 6 | G2: 7 | H2: 8 | I2: 9 | J2: 10 | K2: 11 | L2: 12 | M2: 13 | N2: 14 | O2: 15 | P2: 16 | Q2: 17 | R2: 18 | S2: 19 | T2: 20 | U2: 21 | V2: 22 | W2: 23 | X2: 24 | Y2: 25 | Z2: 26 | AA2: 27 | AB2: 28 | AC2: 29 | AD2: 30 | AE2: 31 | AF2: 32
A3: 호별 | B3: 분양 분류 | D3: 전용면적 | F3: 분양면적 | H3: 공용면적 | N3: 대지지분 | P3: 임대가(vat별도) | S3: 분양가(vat별도) | W3: 부가세 | X3: 총분양가 (vat포함) | Y3: 계약금 (10%)
H4: 층별공용 | J4: 기계/주차 | L4: 공용합계
B5: 구분 | C5: 세부용도 | D5: ㎡ | E5: 평 | F5: ㎡ | G5: 평 | H5: ㎡ | I5: 평 | J5: ㎡ | K5: 평 | L5: ㎡ | M5: 평 | N5: ㎡ | O5: 평 | P5: 평당가 | Q5: 월임대료 | R5: 보증금 | S5: 평당가 | T5: 토지비 | U5: 건축비 | V5: 공급가 | Y5: 분양 | Z5: 임대 | AB5: 층별공용 | AC5: 기계전기실 | AD5: 주차장 | AE5: 기계/주차 | AF5: 공용합계
A6: B401 | B6: 공공성확보시설 | C6: 임대 | D6: 157.29 | E6: 47.580225 | F6: 343.15 | G6: 103.80287 | H6: 62.45 | I6: 18.891125 | J6: 123.41 | K6: 37.331525 | L6: 185.86 | M6: 56.22265 | N6: 52.03 | O6: 15.739075 | P6: 20000 | Q6: 2077000 | R6: 20770000 | W6: 207700 | X6: 2284700 | Z6: 2077000 | AA6: 잔여분 | AB6: 62.45 | AC6: 9.64 | AD6: 113.77 | AE6: 123.41 | AF6: 185.86
A7: B402 | B7: 공공성확보시설 | C7: 임대 | D7: 131.09 | E7: 39.654725 | F7: 286 | G7: 86.515 | H7: 52.05 | I7: 15.745125 | J7: 102.86 | K7: 31.11515 | L7: 154.91 | M7: 46.860275 | N7: 43.35 | O7: 13.113375 | P7: 20000 | Q7: 1731000 | R7: 17310000 | W7: 173100 | X7: 1904100 | Z7: 1731000 | AA7: 잔여분 | AB7: 52.05 | AC7: 8.04 | AD7: 94.82 | AE7: 102.86 | AF7: 154.91
A8: B403 | B8: 공공성확보시설 | C8: 임대 | D8: 175.53 | E8: 53.097825 | F8: 382.95 | G8: 115.84237 | H8: 69.69 | I8: 21.081225 | J8: 137.73 | K8: 41.663325 | L8: 207.42 | M8: 62.74455 | N8: 58.04 | O8: 17.5571 | P8: 20000 | Q8: 2317000 | R8: 23170000 | W8: 231700 | X8: 2548700 | Z8: 2317000 | AA8: 잔여분 | AB8: 69.69 | AC8: 10.77 | AD8: 126.96 | AE8: 137.73 | AF8: 207.42
A9: B404 | B9: 공공성확보시설 | C9: 임대 | D9: 41.36 | E9: 12.5114 | F9: 90.24 | G9: 27.2976 | H9: 16.42 | I9: 4.96705 | J9: 32.46 | K9: 9.81915 | L9: 48.88 | M9: 14.7862 | N9: 13.68 | O9: 4.1382 | P9: 20000 | Q9: 546000 | R9: 5460000 | W9: 54600 | X9: 600600 | Z9: 546000 | AA9: 잔여분 | AB9: 16.42 | AC9: 2.54 | AD9: 29.92 | AE9: 32.46 | AF9: 48.88
A10: B405 | B10: 공공성확보시설 | C10: 임대 | D10: 40.61 | E10: 12.284525 | F10: 88.59 | G10: 26.798475 | H10: 16.12 | I10: 4.8763 | J10: 31.86 | K10: 9.63765 | L10: 47.98 | M10: 14.51395 | N10: 13.43 | O10: 4.062575 | P10: 20000 | Q10: 536000 | R10: 5360000 | W10: 53600 | X10: 589600 | Z10: 536000 | AA10: 잔여분 | AB10: 16.12 | AC10: 2.49 | AD10: 29.37 | AE10: 31.86 | AF10: 47.98
A11: B406 | B11: 공공성확보시설 | C11: 임대 | D11: 46.26 | E11: 13.99365 | F11: 100.93 | G11: 30.531325 | H11: 18.37 | I11: 5.556925 | J11: 36.3 | K11: 10.98075 | L11: 54.67 | M11: 16.537675 | N11: 15.3 | O11: 4.62825 | P11: 20000 | Q11: 611000 | R11: 6110000 | W11: 61100 | X11: 672100 | Z11: 611000 | AA11: 잔여분 | AB11: 18.37 | AC11: 2.84 | AD11: 33.46 | AE11: 36.3 | AF11: 54.67
A12: B407 | B12: 공공성확보시설 | C12: 임대 | D12: 45.94 | E12: 13.89685 | F12: 100.23 | G12: 30.319575 | H12: 18.24 | I12: 5.5176 | J12: 36.05 | K12: 10.905125 | L12: 54.29 | M12: 16.422725 | N12: 15.19 | O12: 4.594975 | P12: 20000 | Q12: 607000 | R12: 6070000 | W12: 60700 | X12: 667700 | Z12: 607000 | AA12: 잔여분 | AB12: 18.24 | AC12: 2.82 | AD12: 33.23 | AE12: 36.05 | AF12: 54.29
A13: B408 | B13: 공공성확보시설 | C13: 임대 | D13: 54.79 | E13: 16.573975 | F13: 119.53 | G13: 36.157825 | H13: 21.75 | I13: 6.579375 | J13: 42.99 | K13: 13.004475 | L13: 64.74 | M13: 19.58385 | N13: 18.12 | O13: 5.4813 | P13: 20000 | Q13: 724000 | R13: 7240000 | W13: 72400 | X13: 796400 | Z13: 724000 | AA13: 잔여분 | AB13: 21.75 | AC13: 3.36 | AD13: 39.63 | AE13: 42.99 | AF13: 64.74
A14: B409 | B14: 공공성확보시설 | C14: 임대 | D14: 166.02 | E14: 50.22105 | F14: 362.21 | G14: 109.56853 | H14: 65.92 | I14: 19.9408 | J14: 130.27 | K14: 39.406675 | L14: 196.19 | M14: 59.347475 | N14: 54.9 | O14: 16.60725 | P14: 20000 | Q14: 2192000 | R14: 21920000 | W14: 219200 | X14: 2411200 | Z14: 2192000 | AA14: 잔여분 | AB14: 65.92 | AC14: 10.19 | AD14: 120.08 | AE14: 130.27 | AF14: 196.19
A15: B410 | B15: 공공성확보시설 | C15: 임대 | D15: 37 | E15: 11.1925 | F15: 80.72 | G15: 24.4178 | H15: 14.69 | I15: 4.443725 | J15: 29.03 | K15: 8.781575 | L15: 43.72 | M15: 13.2253 | N15: 12.24 | O15: 3.7026 | P15: 20000 | Q15: 489000 | R15: 4890000 | W15: 48900 | X15: 537900 | Z15: 489000 | AA15: 잔여분 | AB15: 14.69 | AC15: 2.27 | AD15: 26.76 | AE15: 29.03 | AF15: 43.72
A16: B411 | B16: 공공성확보시설 | C16: 임대 | D16: 37.69 | E16: 11.401225 | F16: 82.22 | G16: 24.87155 | H16: 14.96 | I16: 4.5254 | J16: 29.57 | K16: 8.944925 | L16: 44.53 | M16: 13.470325 | N16: 12.46 | O16: 3.76915 | P16: 20000 | Q16: 498000 | R16: 4980000 | W16: 49800 | X16: 547800 | Z16: 498000 | AA16: 잔여분 | AB16: 14.96 | AC16: 2.31 | AD16: 27.26 | AE16: 29.57 | AF16: 44.53
A17: B412 | B17: 공공성확보시설 | C17: 임대 | D17: 26.87 | E17: 8.128175 | F17: 58.63 | G17: 17.735575 | H17: 10.67 | I17: 3.227675 | J17: 21.09 | K17: 6.379725 | L17: 31.76 | M17: 9.6074 | N17: 8.89 | O17: 2.689225 | P17: 20000 | Q17: 355000 | R17: 3550000 | W17: 35500 | X17: 390500 | Z17: 355000 | AA17: 잔여분 | AB17: 10.67 | AC17: 1.65 | AD17: 19.44 | AE17: 21.09 | AF17: 31.76
A18: 지하 4층 소계 | C18: 12 | D18: 960.45 | E18: 290.53613 | F18: 2095.4 | G18: 633.8585 | H18: 381.33 | I18: 115.35233 | J18: 753.62 | K18: 227.97005 | L18: 1134.95 | M18: 343.32237 | N18: 317.63 | O18: 96.083075 | P18: 20009.198 | Q18: 12683000 | R18: 126830000 | T18: 0 | U18: 0 | V18: 0 | W18: 1268300 | X18: 13951300
A19: B301 | B19: 공공성확보시설 | C19: 임대 | D19: 157.29 | E19: 47.580225 | F19: 343.16 | G19: 103.8059 | H19: 62.45 | I19: 18.891125 | J19: 123.42 | K19: 37.33455 | L19: 185.87 | M19: 56.225675 | N19: 52.01 | O19: 15.733025 | P19: 20000 | Q19: 2077000 | R19: 20770000 | W19: 207700 | X19: 2284700 | Z19: 2077000 | AA19: 잔여분 | AB19: 62.45 | AC19: 9.65 | AD19: 113.77 | AE19: 123.42 | AF19: 185.87
A20: B302 | B20: 공공성확보시설 | C20: 임대 | D20: 175.53 | E20: 53.097825 | F20: 382.95 | G20: 115.84237 | H20: 69.69 | I20: 21.081225 | J20: 137.73 | K20: 41.663325 | L20: 207.42 | M20: 62.74455 | N20: 58.04 | O20: 17.5571 | P20: 20000 | Q20: 2317000 | R20: 23170000 | W20: 231700 | X20: 2548700 | Z20: 2317000 | AA20: 잔여분 | AB20: 69.69 | AC20: 10.77 | AD20: 126.96 | AE20: 137.73 | AF20: 207.42
A21: B303 | B21: 공공성확보시설 | C21: 임대 | D21: 40.58 | E21: 12.27545 | F21: 88.53 | G21: 26.780325 | H21: 16.11 | I21: 4.873275 | J21: 31.84 | K21: 9.6316 | L21: 47.95 | M21: 14.504875 | N21: 13.42 | O21: 4.05955 | P21: 20000 | Q21: 536000 | R21: 5360000 | W21: 53600 | X21: 589600 | Z21: 536000 | AA21: 잔여분 | AB21: 16.11 | AC21: 2.49 | AD21: 29.35 | AE21: 31.84 | AF21: 47.95
